Workbook

Sheet Project & Task Tracker
A1: PROJECT & TASK TRACKER
A3: Project / Initiative | B3: Task / Deliverable | C3: Team Member | D3: Team | E3: Champion / Owner | F3: Priority | G3: Start Date | H3: Target Date | I3: Completed Date | J3: Status | K3: On Time? (auto) | L3: Delay Reason | M3: Delay Reason Validated? | N3: Remarks | O3: Monthly Individual Target (Number) | P3: Monthly Achieved (Number) | Q3: Achievement % (auto)
A4: Sales Performance | B4: Call Volume 200 Calls Per Day | C4: Babita | D4: Sales | E4: Rajesh | F4: Medium | G4: 46266 | H4: 46295 | J4: Completed | K4: =IF(I4="","",IF(I4<=H4,"Yes","No")) | O4: 4400 | Q4: =IFERROR(IF(OR(O4="",O4=0),"",P4/O4),"") -> 0%
A5: Sales Performance | B5: Client Interaction 100 Calls Per Day (50% of Calls Done) | C5: Babita | D5: Sales | E5: Rajesh | F5: Medium | G5: 46266 | H5: 46295 | J5: Ongoing | K5: =IF(I5="","",IF(I5<=H5,"Yes","No")) | O5: 2200 | Q5: =IFERROR(IF(OR(O5="",O5=0),"",P5/O5),"") -> 0%
A6: Sales Performance | B6: Accounts Target Monthly 440 Accounts | C6: Babita | D6: Sales | E6: Rajesh | F6: High | G6: 46266 | H6: 46295 | J6: Ongoing | K6: =IF(I6="","",IF(I6<=H6,"Yes","No")) | O6: 440 | Q6: =IFERROR(IF(OR(O6="",O6=0),"",P6/O6),"") -> 0%
A7: Sales Performance | B7: Call Volume 200 Calls Per Day | C7: Kulwinder | D7: Sales | E7: Rajesh | F7: Medium | G7: 46266 | H7: 46295 | I7: 46295 | J7: Completed | K7: =IF(I7="","",IF(I7<=H7,"Yes","No")) -> Yes | O7: 4400 | P7: 4000 | Q7: =IFERROR(IF(OR(O7="",O7=0),"",P7/O7),"") -> 91%
A8: Sales Performance | B8: Client Interaction 100 Calls Per Day (50% of Calls Done) | C8: Kulwinder | D8: Sales | E8: Rajesh | F8: Medium | G8: 46266 | H8: 46295 | K8: =IF(I8="","",IF(I8<=H8,"Yes","No")) | O8: 2200 | Q8: =IFERROR(IF(OR(O8="",O8=0),"",P8/O8),"") -> 0%
A9: Sales Performance | B9: Accounts Target Monthly 440 Accounts | C9: Kulwinder | D9: Sales | E9: Rajesh | F9: High | G9: 46266 | H9: 46295 | K9: =IF(I9="","",IF(I9<=H9,"Yes","No")) | O9: 440 | Q9: =IFERROR(IF(OR(O9="",O9=0),"",P9/O9),"") -> 0%
A10: Sales Performance | B10: Call Volume 194 Calls Per Day | C10: Rahul | D10: Sales | E10: Rajesh | F10: Medium | G10: 46266 | H10: 46295 | K10: =IF(I10="","",IF(I10<=H10,"Yes","No")) | O10: 4268 | Q10: =IFERROR(IF(OR(O10="",O10=0),"",P10/O10),"") -> 0%
A11: Sales Performance | B11: Client Interaction 97 Calls Per Day (50% of Calls Done) | C11: Rahul | D11: Sales | E11: Rajesh | F11: Medium | G11: 46266 | H11: 46295 | K11: =IF(I11="","",IF(I11<=H11,"Yes","No")) | O11: 2134 | Q11: =IFERROR(IF(OR(O11="",O11=0),"",P11/O11),"") -> 0%
A12: Sales Performance | B12: Accounts Target Monthly 400 Accounts | C12: Rahul | D12: Sales | E12: Rajesh | F12: High | G12: 46266 | H12: 46295 | K12: =IF(I12="","",IF(I12<=H12,"Yes","No")) | O12: 400 | Q12: =IFERROR(IF(OR(O12="",O12=0),"",P12/O12),"") -> 0%
A13: Sales Performance | B13: Call Volume 200 Calls Per Day | C13: Nadeem | D13: Sales | E13: Rajesh | F13: Medium | G13: 46266 | H13: 46295 | K13: =IF(I13="","",IF(I13<=H13,"Yes","No")) | O13: 4400 | Q13: =IFERROR(IF(OR(O13="",O13=0),"",P13/O13),"") -> 0%
A14: Sales Performance | B14: Client Interaction 100 Calls Per Day (50% of Calls Done) | C14: Nadeem | D14: Sales | E14: Rajesh | F14: Medium | G14: 46266 | H14: 46295 | K14: =IF(I14="","",IF(I14<=H14,"Yes","No")) | O14: 2200 | Q14: =IFERROR(IF(OR(O14="",O14=0),"",P14/O14),"") -> 0%
A15: Sales Performance | B15: Accounts Target Monthly 440 Accounts | C15: Nadeem | D15: Sales | E15: Rajesh | F15: High | G15: 46266 | H15: 46295 | K15: =IF(I15="","",IF(I15<=H15,"Yes","No")) | O15: 440 | Q15: =IFERROR(IF(OR(O15="",O15=0),"",P15/O15),"") -> 0%
A16: Sales Performance | B16: Call Volume 200 Calls Per Day | C16: Upasana | D16: Sales | E16: =IFERROR(AVERAGEIFS('Project & Task Tracker'!Q4:Q56,'Project & Task Tracker'!$C$4:$C$46,$A16),"") | F16: Medium | G16: 46266 | H16: 46295 | K16: =IF(I16="","",IF(I16<=H16,"Yes","No")) | O16: 4400 | Q16: =IFERROR(IF(OR(O16="",O16=0),"",P16/O16),"") -> 0%
A17: Sales Performance | B17: Client Interaction 100 Calls Per Day (50% of Calls Done) | C17: Upasana | D17: Sales | E17: Rajesh | F17: Medium | G17: 46266 | H17: 46295 | K17: =IF(I17="","",IF(I17<=H17,"Yes","No")) | O17: 2200 | Q17: =IFERROR(IF(OR(O17="",O17=0),"",P17/O17),"") -> 0%
A18: Sales Performance | B18: Accounts Target Monthly 440 Accounts | C18: Upasana | D18: Sales | E18: Rajesh | F18: High | G18: 46266 | H18: 46295 | K18: =IF(I18="","",IF(I18<=H18,"Yes","No")) | O18: 440 | Q18: =IFERROR(IF(OR(O18="",O18=0),"",P18/O18),"") -> 0%
A19: Sales Performance | B19: Call Volume 180 Calls Per Day | C19: Anshul | D19: Sales | E19: Rajesh | F19: Medium | G19: 46266 | H19: 46295 | K19: =IF(I19="","",IF(I19<=H19,"Yes","No")) | O19: 3960 | Q19: =IFERROR(IF(OR(O19="",O19=0),"",P19/O19),"") -> 0%
A20: Sales Performance | B20: Client Interaction 72 Calls Per Day (40% of Calls Done) | C20: Anshul | D20: Sales | E20: Rajesh | F20: Medium | G20: 46266 | H20: 46295 | K20: =IF(I20="","",IF(I20<=H20,"Yes","No")) | O20: 1584 | Q20: =IFERROR(IF(OR(O20="",O20=0),"",P20/O20),"") -> 0%
A21: Sales Performance | B21: Accounts Target Monthly 390 Accounts | C21: Anshul | D21: Sales | E21: Rajesh | F21: High | G21: 46266 | H21: 46295 | K21: =IF(I21="","",IF(I21<=H21,"Yes","No")) | O21: 390 | Q21: =IFERROR(IF(OR(O21="",O21=0),"",P21/O21),"") -> 0%
A22: Sales Performance | B22: Call Volume 200 Calls Per Day | C22: Alishba | D22: Sales | E22: Rajesh | F22: Medium | G22: 46266 | H22: 46295 | K22: =IF(I22="","",IF(I22<=H22,"Yes","No")) | O22: 4400 | Q22: =IFERROR(IF(OR(O22="",O22=0),"",P22/O22),"") -> 0%
A23: Sales Performance | B23: Client Interaction 100 Calls Per Day (50% of Calls Done) | C23: Alishba | D23: Sales | E23: Rajesh | F23: Medium | G23: 46266 | H23: 46295 | K23: =IF(I23="","",IF(I23<=H23,"Yes","No")) | O23: 2200 | Q23: =IFERROR(IF(OR(O23="",O23=0),"",P23/O23),"") -> 0%
A24: Sales Performance | B24: Accounts Target Monthly 440 Accounts | C24: Alishba | D24: Sales | E24: Rajesh | F24: High | G24: 46266 | H24: 46295 | K24: =IF(I24="","",IF(I24<=H24,"Yes","No")) | O24: 440 | Q24: =IFERROR(IF(OR(O24="",O24=0),"",P24/O24),"") -> 0%
A25: Sales Performance | B25: Call Volume 200 Calls Per Day | C25: Rajat | D25: Sales | E25: Rajesh | F25: Medium | G25: 46266 | H25: 46295 | K25: =IF(I25="","",IF(I25<=H25,"Yes","No")) | O25: 4400 | Q25: =IFERROR(IF(OR(O25="",O25=0),"",P25/O25),"") -> 0%
A26: Sales Performance | B26: Client Interaction 100 Calls Per Day (50% of Calls Done) | C26: Rajat | D26: Sales | E26: Rajesh | F26: Medium | G26: 46266 | H26: 46295 | K26: =IF(I26="","",IF(I26<=H26,"Yes","No")) | O26: 2200 | Q26: =IFERROR(IF(OR(O26="",O26=0),"",P26/O26),"") -> 0%
A27: Sales Performance | B27: Accounts Target Monthly 440 Accounts | C27: Rajat | D27: Sales | E27: Rajesh | F27: High | G27: 46266 | H27: 46295 | K27: =IF(I27="","",IF(I27<=H27,"Yes","No")) | O27: 440 | Q27: =IFERROR(IF(OR(O27="",O27=0),"",P27/O27),"") -> 0%
A28: Sales Performance | B28: Call Volume 200 Calls Per Day | C28: Ujjwala | D28: Sales | E28: Rajesh | F28: Medium | G28: 46266 | H28: 46295 | K28: =IF(I28="","",IF(I28<=H28,"Yes","No")) | O28: 4400 | Q28: =IFERROR(IF(OR(O28="",O28=0),"",P28/O28),"") -> 0%
... A33: Sales Performance | B33: Accounts Target Monthly 330 Accounts | C33: Ramandeep | D33: Sales | E33: Rajesh | F33: High | G33: 46266 | H33: 46295 | K33: =IF(I33="","",IF(I33<=H33,"Yes","No")) | O33: 330 | Q33: =IFERROR(IF(OR(O33="",O33=0),"",P33/O33),"") -> 0%
A34: Sales Performance | B34: Call Volume 190 Calls Per Day | C34: Tanu | D34: Sales | E34: Rajesh | F34: Medium | G34: 46266 | H34: 46295 | I34: 46295 | J34: Completed | K34: =IF(I34="","",IF(I34<=H34,"Yes","No")) -> Yes | O34: 4180 | P34: 4000 | Q34: =IFERROR(IF(OR(O34="",O34=0),"",P34/O34),"") -> 96%
A35: Sales Performance | B35: Client Interaction 85 Calls Per Day (45% of Calls Done) | C35: Tanu | D35: Sales | E35: Rajesh | F35: Medium | G35: 46266 | H35: 46295 | I35: 46295 | J35: Completed | K35: =IF(I35="","",IF(I35<=H35,"Yes","No")) -> Yes | O35: 1881 | Q35: =IFERROR(IF(OR(O35="",O35=0),"",P35/O35),"") -> 0% | R35: =96/3 -> 32
A36: Sales Performance | B36: Accounts Target Monthly 410 Accounts | C36: Tanu | D36: Sales | E36: Rajesh | F36: High | G36: 46266 | H36: 46295 | I36: 46295 | J36: Completed | K36: =IF(I36="","",IF(I36<=H36,"Yes","No")) -> Yes | O36: 410 | Q36: =IFERROR(IF(OR(O36="",O36=0),"",P36/O36),"") -> 0%
A37: Sales Performance | B37: Call Volume 150 Calls Per Day | C37: Sakshi | D37: Sales | E37: Rajesh | F37: Medium | G37: 46266 | H37: 46295 | I37: 46295 | J37: Completed | K37: =IF(I37="","",IF(I37<=H37,"Yes","No")) -> Yes | O37: 3300 | Q37: =IFERROR(IF(OR(O37="",O37=0),"",P37/O37),"") -> 0%
A38: Sales Performance | B38: Client Interaction 60 Calls Per Day (40% of Calls Done) | C38: Sakshi | D38: Sales | E38: Rajesh | F38: Medium | G38: 46266 | H38: 46295 | K38: =IF(I38="","",IF(I38<=H38,"Yes","No")) | O38: 1320 | Q38: =IFERROR(IF(OR(O38="",O38=0),"",P38/O38),"") -> 0%
A39: Sales Performance | B39: Accounts Target Monthly 300 Accounts | C39: Sakshi | D39: Sales | E39: Rajesh | F39: High | G39: 46266 | H39: 46295 | K39: =IF(I39="","",IF(I39<=H39,"Yes","No")) | O39: 300 | Q39: =IFERROR(IF(OR(O39="",O39=0),"",P39/O39),"") -> 0%
A40: Sales Performance | B40: Team Call Volume 200 Calls Per Day | C40: Rajesh | D40: Sales | E40: Gurjot Sodhi | F40: Medium | G40: 46266 | H40: 46295 | I40: 46295 | J40: Completed | K40: =IF(I40="","",IF(I40<=H40,"Yes","No")) -> Yes | O40: 49808 | P40: 50000 | Q40: =IFERROR(IF(OR(O40="",O40=0),"",P40/O40),"") -> 100%
A41: Sales Performance | B41: Team Client Interaction 100 Calls Per Day (50% of Calls Done) | C41: Rajesh | D41: Sales | E41: Gurjot Sodhi | F41: Medium | G41: 46266 | H41: 46295 | I41: 46295 | J41: Completed | K41: =IF(I41="","",IF(I41<=H41,"Yes","No")) -> Yes | O41: 23639 | P41: 25000 | Q41: =IFERROR(IF(OR(O41="",O41=0),"",P41/O41),"") -> 106%
A42: Sales Performance | B42: Team Accounts Target Monthly 440 Accounts | C42: Rajesh | D42: Sales | E42: Gurjot Sodhi | F42: High | G42: 46266 | H42: 46295 | I42: 46295 | J42: Completed | K42: =IF(I42="","",IF(I42<=H42,"Yes","No")) -> Yes | O42: 4910 | P42: 7000 | Q42: =IFERROR(IF(OR(O42="",O42=0),"",P42/O42),"") -> 143%
A43: Sales Performance | B43: Overall Accounts Conversion | C43: Rajesh | D43: Sales | E43: Gurjot Sodhi | F43: High | G43: 46266 | H43: 46295 | K43: =IF(I43="","",IF(I43<=H43,"Yes","No")) | O43: NA (40% Of Leads) | Q43: =IFERROR(IF(OR(O43="",O43=0),"",P43/O43),"")
A44: Sales Performance | B44: Team Call Volume 185 Calls Per Day | C44: Durga | D44: Sales | E44: Gurjot Sodhi | F44: High | G44: 46266 | H44: 46295 | K44: =IF(I44="","",IF(I44<=H44,"Yes","No")) | O44: 4080 | Q44: =IFERROR(IF(OR(O44="",O44=0),"",P44/O44),"") -> 0%
A45: Sales Performance | B45: Team Client Interaction 90 Calls Per Day (50% of Calls Done) | C45: Durga | D45: Sales | E45: Gurjot Sodhi | F45: High | G45: 46266 | H45: 46295 | K45: =IF(I45="","",IF(I45<=H45,"Yes","No")) | O45: 1980 | Q45: =IFERROR(IF(OR(O45="",O45=0),"",P45/O45),"") -> 0%
...

Sheet Rewards & Recognition
A1: REWARDS & RECOGNITION
A3: Team Member | B3: Team | C3: Tasks Completed On Time (auto) | D3: Tasks Delayed (auto) | E3: Avg Achievement % (auto) | F3: Avg Quality | G3: Csat | H3: Compliance | I3: Innovation | J3: Bonus Points (you type this) | K3: Total Points (auto) | L3: Reward Tier (auto) | M3: Reward Given | N3: Date Awarded | O3: Approved By
A4: Babita | B4: ='Project & Task Tracker'!D4 -> Sales | C4: =IF($A4="",0,COUNTIFS('Project & Task Tracker'!$C$4:$C$56,$A4,'Project & Task Tracker'!$K$4:$K$56,"Yes")+COUNTIFS('Extra Tasks'!$C$3:$C$40,$A4,'Extra Tasks'!$K$3:$K$40,"Yes")) -> 0 | D4: =IF($A4="",0,COUNTIFS('Project & Task Tracker'!$C$4:$C$56,$A4,'Project & Task Tracker'!$J$4:$J$56,"Delayed")+COUNTIFS('Extra Tasks'!$C$3:$C$40,$A4,'Extra Tasks'!$J$3:$J$40,"Delayed")) -> 0 | E4: =IFERROR((SUMIFS('Project & Task Tracker'!$Q$4:$Q$56,'Project & Task Tracker'!$C$4:$C$56,$A4)+SUMIFS('Extra Tasks'!$Q$3:$Q$40,'Extra Tasks'!$C$3:$C$40,$A4))/(COUNTIFS('Project & Task Tracker'!$C$4:$C$56,$A4,'Project & Task Tracker'!$Q$4:$Q$56,">=0")+COUNTIFS('Extra Tasks'!$C$3:$C$40,$A4,'Extra Tasks'!$Q$3:$Q$40,">=0")),"") | K4: =IF(E4="",0,IF(E4>=1,50,IF(E4>=0.9,30,0)))+IFERROR(J4,0)-D4 -> 0 | L4: =IF($A4="","",IF(K4>=50,"Gold",IF(K4>=30,"Silver",IF(K4>=15,"Bronze","No Reward Yet")))) -> No Reward Yet
A5: Kulwinder | B5: ='Project & Task Tracker'!D5 K:K -> #VALUE! | C5: =IF($A5="",0,COUNTIFS('Project & Task Tracker'!$C$4:$C$56,$A5,'Project & Task Tracker'!$K$4:$K$56,"Yes")+COUNTIFS('Extra Tasks'!$C$3:$C$40,$A5,'Extra Tasks'!$K$3:$K$40,"Yes")) -> 1 | D5: =IF($A5="",0,COUNTIFS('Project & Task Tracker'!$C$4:$C$56,$A5,'Project & Task Tracker'!$J$4:$J$56,"Delayed")+COUNTIFS('Extra Tasks'!$C$3:$C$40,$A5,'Extra Tasks'!$J$3:$J$40,"Delayed")) -> 0 | E5: =IFERROR((SUMIFS('Project & Task Tracker'!$Q$4:$Q$56,'Project & Task Tracker'!$C$4:$C$56,$A5)+SUMIFS('Extra Tasks'!$Q$3:$Q$40,'Extra Tasks'!$C$3:$C$40,$A5))/(COUNTIFS('Project & Task Tracker'!$C$4:$C$56,$A5,'Project & Task Tracker'!$Q$4:$Q$56,">=0")+COUNTIFS('Extra Tasks'!$C$3:$C$40,$A5,'Extra Tasks'!$Q$3:$Q$40,">=0")),"") | K5: =IF(E5="",0,IF(E5>=1,50,IF(E5>=0.9,30,0)))+IFERROR(J5,0)-D5 -> 0 | L5: =IF($A5="","",IF(K5>=50,"Gold",IF(K5>=30,"Silver",IF(K5>=15,"Bronze","No Reward Yet")))) -> No Reward Yet
A6: Rahul | B6: ='Project & Task Tracker'!D6 -> Sales | C6: =IF($A6="",0,COUNTIFS('Project & Task Tracker'!$C$4:$C$56,$A6,'Project & Task Tracker'!$K$4:$K$56,"Yes")+COUNTIFS('Extra Tasks'!$C$3:$C$40,$A6,'Extra Tasks'!$K$3:$K$40,"Yes")) -> 0 | D6: =IF($A6="",0,COUNTIFS('Project & Task Tracker'!$C$4:$C$56,$A6,'Project & Task Tracker'!$J$4:$J$56,"Delayed")+COUNTIFS('Extra Tasks'!$C$3:$C$40,$A6,'Extra Tasks'!$J$3:$J$40,"Delayed")) -> 0 | E6: =IFERROR((SUMIFS('Project & Task Tracker'!$Q$4:$Q$56,'Project & Task Tracker'!$C$4:$C$56,$A6)+SUMIFS('Extra Tasks'!$Q$3:$Q$40,'Extra Tasks'!$C$3:$C$40,$A6))/(COUNTIFS('Project & Task Tracker'!$C$4:$C$56,$A6,'Project & Task Tracker'!$Q$4:$Q$56,">=0")+COUNTIFS('Extra Tasks'!$C$3:$C$40,$A6,'Extra Tasks'!$Q$3:$Q$40,">=0")),"") | K6: =IF(E6="",0,IF(E6>=1,50,IF(E6>=0.9,30,0)))+IFERROR(J6,0)-D6 -> 0 | L6: =IF($A6="","",IF(K6>=50,"Gold",IF(K6>=30,"Silver",IF(K6>=15,"Bronze","No Reward Yet")))) -> No Reward Yet
A7: Nadeem | B7: ='Project & Task Tracker'!D7 -> Sales | C7: =IF($A7="",0,COUNTIFS('Project & Task Tracker'!$C$4:$C$56,$A7,'Project & Task Tracker'!$K$4:$K$56,"Yes")+COUNTIFS('Extra Tasks'!$C$3:$C$40,$A7,'Extra Tasks'!$K$3:$K$40,"Yes")) -> 0 | D7: =IF($A7="",0,COUNTIFS('Project & Task Tracker'!$C$4:$C$56,$A7,'Project & Task Tracker'!$J$4:$J$56,"Delayed")+COUNTIFS('Extra Tasks'!$C$3:$C$40,$A7,'Extra Tasks'!$J$3:$J$40,"Delayed")) -> 0 | E7: =IFERROR((SUMIFS('Project & Task Tracker'!$Q$4:$Q$56,'Project & Task Tracker'!$C$4:$C$56,$A7)+SUMIFS('Extra Tasks'!$Q$3:$Q$40,'Extra Tasks'!$C$3:$C$40,$A7))/(COUNTIFS('Project & Task Tracker'!$C$4:$C$56,$A7,'Project & Task Tracker'!$Q$4:$Q$56,">=0")+COUNTIFS('Extra Tasks'!$C$3:$C$40,$A7,'Extra Tasks'!$Q$3:$Q$40,">=0")),"") | K7: =IF(E7="",0,IF(E7>=1,50,IF(E7>=0.9,30,0)))+IFERROR(J7,0)-D7 -> 0 | L7: =IF($A7="","",IF(K7>=50,"Gold",IF(K7>=30,"Silver",IF(K7>=15,"Bronze","No Reward Yet")))) -> No Reward Yet
A8: Upasana | B8: ='Project & Task Tracker'!D8 -> Sales | C8: =IF($A8="",0,COUNTIFS('Project & Task Tracker'!$C$4:$C$56,$A8,'Project & Task Tracker'!$K$4:$K$56,"Yes")+COUNTIFS('Extra Tasks'!$C$3:$C$40,$A8,'Extra Tasks'!$K$3:$K$40,"Yes")) -> 0 | D8: =IF($A8="",0,COUNTIFS('Project & Task Tracker'!$C$4:$C$56,$A8,'Project & Task Tracker'!$J$4:$J$56,"Delayed")+COUNTIFS('Extra Tasks'!$C$3:$C$40,$A8,'Extra Tasks'!$J$3:$J$40,"Delayed")) -> 0 | E8: =IFERROR((SUMIFS('Project & Task Tracker'!$Q$4:$Q$56,'Project & Task Tracker'!$C$4:$C$56,$A8)+SUMIFS('Extra Tasks'!$Q$3:$Q$40,'Extra Tasks'!$C$3:$C$40,$A8))/(COUNTIFS('Project & Task Tracker'!$C$4:$C$56,$A8,'Project & Task Tracker'!$Q$4:$Q$56,">=0")+COUNTIFS('Extra Tasks'!$C$3:$C$40,$A8,'Extra Tasks'!$Q$3:$Q$40,">=0")),"") | K8: =IF(E8="",0,IF(E8>=1,50,IF(E8>=0.9,30,0)))+IFERROR(J8,0)-D8 -> 0 | L8: =IF($A8="","",IF(K8>=50,"Gold",IF(K8>=30,"Silver",IF(K8>=15,"Bronze","No Reward Yet")))) -> No Reward Yet
A9: Anshul | B9: ='Project & Task Tracker'!D9 -> Sales | C9: =IF($A9="",0,COUNTIFS('Project & Task Tracker'!$C$4:$C$56,$A9,'Project & Task Tracker'!$K$4:$K$56,"Yes")+COUNTIFS('Extra Tasks'!$C$3:$C$40,$A9,'Extra Tasks'!$K$3:$K$40,"Yes")) -> 0 | D9: =IF($A9="",0,COUNTIFS('Project & Task Tracker'!$C$4:$C$56,$A9,'Project & Task Tracker'!$J$4:$J$56,"Delayed")+COUNTIFS('Extra Tasks'!$C$3:$C$40,$A9,'Extra Tasks'!$J$3:$J$40,"Delayed")) -> 0 | E9: =IFERROR((SUMIFS('Project & Task Tracker'!$Q$4:$Q$56,'Project & Task Tracker'!$C$4:$C$56,$A9)+SUMIFS('Extra Tasks'!$Q$3:$Q$40,'Extra Tasks'!$C$3:$C$40,$A9))/(COUNTIFS('Project & Task Tracker'!$C$4:$C$56,$A9,'Project & Task Tracker'!$Q$4:$Q$56,">=0")+COUNTIFS('Extra Tasks'!$C$3:$C$40,$A9,'Extra Tasks'!$Q$3:$Q$40,">=0")),"") | K9: =IF(E9="",0,IF(E9>=1,50,IF(E9>=0.9,30,0)))+IFERROR(J9,0)-D9 -> 0 | L9: =IF($A9="","",IF(K9>=50,"Gold",IF(K9>=30,"Silver",IF(K9>=15,"Bronze","No Reward Yet")))) -> No Reward Yet
A10: Alishba | B10: ='Project & Task Tracker'!D10 -> Sales | C10: =IF($A10="",0,COUNTIFS('Project & Task Tracker'!$C$4:$C$56,$A10,'Project & Task Tracker'!$K$4:$K$56,"Yes")+COUNTIFS('Extra Tasks'!$C$3:$C$40,$A10,'Extra Tasks'!$K$3:$K$40,"Yes")) -> 0 | D10: =IF($A10="",0,COUNTIFS('Project & Task Tracker'!$C$4:$C$56,$A10,'Project & Task Tracker'!$J$4:$J$56,"Delayed")+COUNTIFS('Extra Tasks'!$C$3:$C$40,$A10,'Extra Tasks'!$J$3:$J$40,"Delayed")) -> 0 | E10: =IFERROR((SUMIFS('Project & Task Tracker'!$Q$4:$Q$56,'Project & Task Tracker'!$C$4:$C$56,$A10)+SUMIFS('Extra Tasks'!$Q$3:$Q$40,'Extra Tasks'!$C$3:$C$40,$A10))/(COUNTIFS('Project & Task Tracker'!$C$4:$C$56,$A10,'Project & Task Tracker'!$Q$4:$Q$56,">=0")+COUNTIFS('Extra Tasks'!$C$3:$C$40,$A10,'Extra Tasks'!$Q$3:$Q$40,">=0")),"") | K10: =IF(E10="",0,IF(E10>=1,50,IF(E10>=0.9,30,0)))+IFERROR(J10,0)-D10 -> 0 | L10: =IF($A10="","",IF(K10>=50,"Gold",IF(K10>=30,"Silver",IF(K10>=15,"Bronze","No Reward Yet")))) -> No Reward Yet
A11: Rajat | B11: ='Project & Task Tracker'!D11 -> Sales | C11: =IF($A11="",0,COUNTIFS('Project & Task Tracker'!$C$4:$C$56,$A11,'Project & Task Tracker'!$K$4:$K$56,"Yes")+COUNTIFS('Extra Tasks'!$C$3:$C$40,$A11,'Extra Tasks'!$K$3:$K$40,"Yes")) -> 0 | D11: =IF($A11="",0,COUNTIFS('Project & Task Tracker'!$C$4:$C$56,$A11,'Project & Task Tracker'!$J$4:$J$56,"Delayed")+COUNTIFS('Extra Tasks'!$C$3:$C$40,$A11,'Extra Tasks'!$J$3:$J$40,"Delayed")) -> 0 | E11: =IFERROR((SUMIFS('Project & Task Tracker'!$Q$4:$Q$56,'Project & Task Tracker'!$C$4:$C$56,$A11)+SUMIFS('Extra Tasks'!$Q$3:$Q$40,'Extra Tasks'!$C$3:$C$40,$A11))/(COUNTIFS('Project & Task Tracker'!$C$4:$C$56,$A11,'Project & Task Tracker'!$Q$4:$Q$56,">=0")+COUNTIFS('Extra Tasks'!$C$3:$C$40,$A11,'Extra Tasks'!$Q$3:$Q$40,">=0")),"") | K11: =IF(E11="",0,IF(E11>=1,50,IF(E11>=0.9,30,0)))+IFERROR(J11,0)-D11 -> 0 | L11: =IF($A11="","",IF(K11>=50,"Gold",IF(K11>=30,"Silver",IF(K11>=15,"Bronze","No Reward Yet")))) -> No Reward Yet
A12: Ujjwala | B12: ='Project & Task Tracker'!D12 -> Sales | C12: =IF($A12="",0,COUNTIFS('Project & Task Tracker'!$C$4:$C$56,$A12,'Project & Task Tracker'!$K$4:$K$56,"Yes")+COUNTIFS('Extra Tasks'!$C$3:$C$40,$A12,'Extra Tasks'!$K$3:$K$40,"Yes")) -> 0 | D12: =IF($A12="",0,COUNTIFS('Project & Task Tracker'!$C$4:$C$56,$A12,'Project & Task Tracker'!$J$4:$J$56,"Delayed")+COUNTIFS('Extra Tasks'!$C$3:$C$40,$A12,'Extra Tasks'!$J$3:$J$40,"Delayed")) -> 0 | E12: =IFERROR((SUMIFS('Project & Task Tracker'!$Q$4:$Q$56,'Project & Task Tracker'!$C$4:$C$56,$A12)+SUMIFS('Extra Tasks'!$Q$3:$Q$40,'Extra Tasks'!$C$3:$C$40,$A12))/(COUNTIFS('Project & Task Tracker'!$C$4:$C$56,$A12,'Project & Task Tracker'!$Q$4:$Q$56,">=0")+COUNTIFS('Extra Tasks'!$C$3:$C$40,$A12,'Extra Tasks'!$Q$3:$Q$40,">=0")),"") | K12: =IF(E12="",0,IF(E12>=1,50,IF(E12>=0.9,30,0)))+IFERROR(J12,0)-D12 -> 0 | L12: =IF($A12="","",IF(K12>=50,"Gold",IF(K12>=30,"Silver",IF(K12>=15,"Bronze","No Reward Yet")))) -> No Reward Yet
A13: Ramandeep | B13: ='Extra Tasks'!D35 -> Sales | C13: =IF($A13="",0,COUNTIFS('Project & Task Tracker'!$C$4:$C$56,$A13,'Project & Task Tracker'!$K$4:$K$56,"Yes")+COUNTIFS('Extra Tasks'!$C$3:$C$40,$A13,'Extra Tasks'!$K$3:$K$40,"Yes")) -> 0 | D13: =IF($A13="",0,COUNTIFS('Project & Task Tracker'!$C$4:$C$56,$A13,'Project & Task Tracker'!$J$4:$J$56,"Delayed")+COUNTIFS('Extra Tasks'!$C$3:$C$40,$A13,'Extra Tasks'!$J$3:$J$40,"Delayed")) -> 0 | E13: =IFERROR((SUMIFS('Project & Task Tracker'!$Q$4:$Q$56,'Project & Task Tracker'!$C$4:$C$56,$A13)+SUMIFS('Extra Tasks'!$Q$3:$Q$40,'Extra Tasks'!$C$3:$C$40,$A13))/(COUNTIFS('Project & Task Tracker'!$C$4:$C$56,$A13,'Project & Task Tracker'!$Q$4:$Q$56,">=0")+COUNTIFS('Extra Tasks'!$C$3:$C$40,$A13,'Extra Tasks'!$Q$3:$Q$40,">=0")),"") | K13: =IF(E13="",0,IF(E13>=1,50,IF(E13>=0.9,30,0)))+IFERROR(J13,0)-D13 -> 0 | L13: =IF($A13="","",IF(K13>=50,"Gold",IF(K13>=30,"Silver",IF(K13>=15,"Bronze","No Reward Yet")))) -> No Reward Yet
A14: Tanu | B14: ='Extra Tasks'!D36 -> Sales | C14: =IF($A14="",0,COUNTIFS('Project & Task Tracker'!$C$4:$C$56,$A14,'Project & Task Tracker'!$K$4:$K$56,"Yes")+COUNTIFS('Extra Tasks'!$C$3:$C$40,$A14,'Extra Tasks'!$K$3:$K$40,"Yes")) -> 3 | D14: =IF($A14="",0,COUNTIFS('Project & Task Tracker'!$C$4:$C$56,$A14,'Project & Task Tracker'!$J$4:$J$56,"Delayed")+COUNTIFS('Extra Tasks'!$C$3:$C$40,$A14,'Extra Tasks'!$J$3:$J$40,"Delayed")) -> 0 | E14: =IFERROR((SUMIFS('Project & Task Tracker'!$Q$4:$Q$56,'Project & Task Tracker'!$C$4:$C$56,$A14)+SUMIFS('Extra Tasks'!$Q$3:$Q$40,'Extra Tasks'!$C$3:$C$40,$A14))/(COUNTIFS('Project & Task Tracker'!$C$4:$C$56,$A14,'Project & Task Tracker'!$Q$4:$Q$56,">=0")+COUNTIFS('Extra Tasks'!$C$3:$C$40,$A14,'Extra Tasks'!$Q$3:$Q$40,">=0")),"") | K14: =IF(E14="",0,IF(E14>=1,50,IF(E14>=0.9,30,0)))+IFERROR(J14,0)-D14 -> 0 | L14: =IF($A14="","",IF(K14>=50,"Gold",IF(K14>=30,"Silver",IF(K14>=15,"Bronze","No Reward Yet")))) -> No Reward Yet
A15: Sakshi | B15: ='Project & Task Tracker'!D13 -> Sales | C15: =IF($A15="",0,COUNTIFS('Project & Task Tracker'!$C$4:$C$56,$A15,'Project & Task Tracker'!$K$4:$K$56,"Yes")+COUNTIFS('Extra Tasks'!$C$3:$C$40,$A15,'Extra Tasks'!$K$3:$K$40,"Yes")) -> 1 | D15: =IF($A15="",0,COUNTIFS('Project & Task Tracker'!$C$4:$C$56,$A15,'Project & Task Tracker'!$J$4:$J$56,"Delayed")+COUNTIFS('Extra Tasks'!$C$3:$C$40,$A15,'Extra Tasks'!$J$3:$J$40,"Delayed")) -> 0 | E15: =IFERROR((SUMIFS('Project & Task Tracker'!$Q$4:$Q$56,'Project & Task Tracker'!$C$4:$C$56,$A15)+SUMIFS('Extra Tasks'!$Q$3:$Q$40,'Extra Tasks'!$C$3:$C$40,$A15))/(COUNTIFS('Project & Task Tracker'!$C$4:$C$56,$A15,'Project & Task Tracker'!$Q$4:$Q$56,">=0")+COUNTIFS('Extra Tasks'!$C$3:$C$40,$A15,'Extra Tasks'!$Q$3:$Q$40,">=0")),"") | K15: =IF(E15="",0,IF(E15>=1,50,IF(E15>=0.9,30,0)))+IFERROR(J15,0)-D15 -> 0 | L15: =IF($A15="","",IF(K15>=50,"Gold",IF(K15>=30,"Silver",IF(K15>=15,"Bronze","No Reward Yet")))) -> No Reward Yet
A16: Rajesh | B16: ='Project & Task Tracker'!D14 -> Sales | C16: =IF($A16="",0,COUNTIFS('Project & Task Tracker'!$C$4:$C$56,$A16,'Project & Task Tracker'!$K$4:$K$56,"Yes")+COUNTIFS('Extra Tasks'!$C$3:$C$40,$A16,'Extra Tasks'!$K$3:$K$40,"Yes")) -> 3 | D16: =IF($A16="",0,COUNTIFS('Project & Task Tracker'!$C$4:$C$56,$A16,'Project & Task Tracker'!$J$4:$J$56,"Delayed")+COUNTIFS('Extra Tasks'!$C$3:$C$40,$A16,'Extra Tasks'!$J$3:$J$40,"Delayed")) -> 0 | E16: =IFERROR((SUMIFS('Project & Task Tracker'!$Q$4:$Q$56,'Project & Task Tracker'!$C$4:$C$56,$A16)+SUMIFS('Extra Tasks'!$Q$3:$Q$40,'Extra Tasks'!$C$3:$C$40,$A16))/(COUNTIFS('Project & Task Tracker'!$C$4:$C$56,$A16,'Project & Task Tracker'!$Q$4:$Q$56,">=0")+COUNTIFS('Extra Tasks'!$C$3:$C$40,$A16,'Extra Tasks'!$Q$3:$Q$40,">=0")),"") | K16: =IF(E16="",0,IF(E16>=1,50,IF(E16>=0.9,30,0)))+IFERROR(J16,0)-D16 -> 0 | L16: =IF($A16="","",IF(K16>=50,"Gold",IF(K16>=30,"Silver",IF(K16>=15,"Bronze","No Reward Yet")))) -> No Reward Yet
A17: Durga | B17: ='Project & Task Tracker'!D15 -> Sales | C17: =IF($A17="",0,COUNTIFS('Project & Task Tracker'!$C$4:$C$56,$A17,'Project & Task Tracker'!$K$4:$K$56,"Yes")+COUNTIFS('Extra Tasks'!$C$3:$C$40,$A17,'Extra Tasks'!$K$3:$K$40,"Yes")) -> 0 | D17: =IF($A17="",0,COUNTIFS('Project & Task Tracker'!$C$4:$C$56,$A17,'Project & Task Tracker'!$J$4:$J$56,"Delayed")+COUNTIFS('Extra Tasks'!$C$3:$C$40,$A17,'Extra Tasks'!$J$3:$J$40,"Delayed")) -> 0 | E17: =IFERROR((SUMIFS('Project & Task Tracker'!$Q$4:$Q$56,'Project & Task Tracker'!$C$4:$C$56,$A17)+SUMIFS('Extra Tasks'!$Q$3:$Q$40,'Extra Tasks'!$C$3:$C$40,$A17))/(COUNTIFS('Project & Task Tracker'!$C$4:$C$56,$A17,'Project & Task Tracker'!$Q$4:$Q$56,">=0")+COUNTIFS('Extra Tasks'!$C$3:$C$40,$A17,'Extra Tasks'!$Q$3:$Q$40,">=0")),"") | K17: =IF(E17="",0,IF(E17>=1,50,IF(E17>=0.9,30,0)))+IFERROR(J17,0)-D17 -> 0 | L17: =IF($A17="","",IF(K17>=50,"Gold",IF(K17>=30,"Silver",IF(K17>=15,"Bronze","No Reward Yet")))) -> No Reward Yet
A18: Deepak Moraina | B18: ='Project & Task Tracker'!D16 -> Sales | C18: =IF($A18="",0,COUNTIFS('Project & Task Tracker'!$C$4:$C$56,$A18,'Project & Task Tracker'!$K$4:$K$56,"Yes")+COUNTIFS('Extra Tasks'!$C$3:$C$40,$A18,'Extra Tasks'!$K$3:$K$40,"Yes")) -> 0 | D18: =IF($A18="",0,COUNTIFS('Project & Task Tracker'!$C$4:$C$56,$A18,'Project & Task Tracker'!$J$4:$J$56,"Delayed")+COUNTIFS('Extra Tasks'!$C$3:$C$40,$A18,'Extra Tasks'!$J$3:$J$40,"Delayed")) -> 0 | E18: =IFERROR((SUMIFS('Project & Task Tracker'!$Q$4:$Q$56,'Project & Task Tracker'!$C$4:$C$56,$A18)+SUMIFS('Extra Tasks'!$Q$3:$Q$40,'Extra Tasks'!$C$3:$C$40,$A18))/(COUNTIFS('Project & Task Tracker'!$C$4:$C$56,$A18,'Project & Task Tracker'!$Q$4:$Q$56,">=0")+COUNTIFS('Extra Tasks'!$C$3:$C$40,$A18,'Extra Tasks'!$Q$3:$Q$40,">=0")),"") | K18: =IF(E18="",0,IF(E18>=1,50,IF(E18>=0.9,30,0)))+IFERROR(J18,0)-D18 -> 0 | L18: =IF($A18="","",IF(K18>=50,"Gold",IF(K18>=30,"Silver",IF(K18>=15,"Bronze","No Reward Yet")))) -> No Reward Yet
A19: Anju Kumari | B19: ='Project & Task Tracker'!D17 -> Sales | C19: =IF($A19="",0,COUNTIFS('Project & Task Tracker'!$C$4:$C$56,$A19,'Project & Task Tracker'!$K$4:$K$56,"Yes")+COUNTIFS('Extra Tasks'!$C$3:$C$40,$A19,'Extra Tasks'!$K$3:$K$40,"Yes")) -> 0 | D19: =IF($A19="",0,COUNTIFS('Project & Task Tracker'!$C$4:$C$56,$A19,'Project & Task Tracker'!$J$4:$J$56,"Delayed")+COUNTIFS('Extra Tasks'!$C$3:$C$40,$A19,'Extra Tasks'!$J$3:$J$40,"Delayed")) -> 0 | E19: =IFERROR((SUMIFS('Project & Task Tracker'!$Q$4:$Q$56,'Project & Task Tracker'!$C$4:$C$56,$A19)+SUMIFS('Extra Tasks'!$Q$3:$Q$40,'Extra Tasks'!$C$3:$C$40,$A19))/(COUNTIFS('Project & Task Tracker'!$C$4:$C$56,$A19,'Project & Task Tracker'!$Q$4:$Q$56,">=0")+COUNTIFS('Extra Tasks'!$C$3:$C$40,$A19,'Extra Tasks'!$Q$3:$Q$40,">=0")),"") | K19: =IF(E19="",0,IF(E19>=1,50,IF(E19>=0.9,30,0)))+IFERROR(J19,0)-D19 -> 0 | L19: =IF($A19="","",IF(K19>=50,"Gold",IF(K19>=30,"Silver",IF(K19>=15,"Bronze","No Reward Yet")))) -> No Reward Yet
A20: Neha Solanki | B20: ='Project & Task Tracker'!D18 -> Sales | C20: =IF($A20="",0,COUNTIFS('Project & Task Tracker'!$C$4:$C$56,$A20,'Project & Task Tracker'!$K$4:$K$56,"Yes")+COUNTIFS('Extra Tasks'!$C$3:$C$40,$A20,'Extra Tasks'!$K$3:$K$40,"Yes")) -> 0 | D20: =IF($A20="",0,COUNTIFS('Project & Task Tracker'!$C$4:$C$56,$A20,'Project & Task Tracker'!$J$4:$J$56,"Delayed")+COUNTIFS('Extra Tasks'!$C$3:$C$40,$A20,'Extra Tasks'!$J$3:$J$40,"Delayed")) -> 0 | E20: =IFERROR((SUMIFS('Project & Task Tracker'!$Q$4:$Q$56,'Project & Task Tracker'!$C$4:$C$56,$A20)+SUMIFS('Extra Tasks'!$Q$3:$Q$40,'Extra Tasks'!$C$3:$C$40,$A20))/(COUNTIFS('Project & Task Tracker'!$C$4:$C$56,$A20,'Project & Task Tracker'!$Q$4:$Q$56,">=0")+COUNTIFS('Extra Tasks'!$C$3:$C$40,$A20,'Extra Tasks'!$Q$3:$Q$40,">=0")),"") | K20: =IF(E20="",0,IF(E20>=1,50,IF(E20>=0.9,30,0)))+IFERROR(J20,0)-D20 -> 0 | L20: =IF($A20="","",IF(K20>=50,"Gold",IF(K20>=30,"Silver",IF(K20>=15,"Bronze","No Reward Yet")))) -> No Reward Yet
A21: Pramodh | B21: ='Project & Task Tracker'!D19 -> Sales | C21: =IF($A21="",0,COUNTIFS('Project & Task Tracker'!$C$4:$C$56,$A21,'Project & Task Tracker'!$K$4:$K$56,"Yes")+COUNTIFS('Extra Tasks'!$C$3:$C$40,$A21,'Extra Tasks'!$K$3:$K$40,"Yes")) -> 0 | D21: =IF($A21="",0,COUNTIFS('Project & Task Tracker'!$C$4:$C$56,$A21,'Project & Task Tracker'!$J$4:$J$56,"Delayed")+COUNTIFS('Extra Tasks'!$C$3:$C$40,$A21,'Extra Tasks'!$J$3:$J$40,"Delayed")) -> 0 | E21: =IFERROR((SUMIFS('Project & Task Tracker'!$Q$4:$Q$56,'Project & Task Tracker'!$C$4:$C$56,$A21)+SUMIFS('Extra Tasks'!$Q$3:$Q$40,'Extra Tasks'!$C$3:$C$40,$A21))/(COUNTIFS('Project & Task Tracker'!$C$4:$C$56,$A21,'Project & Task Tracker'!$Q$4:$Q$56,">=0")+COUNTIFS('Extra Tasks'!$C$3:$C$40,$A21,'Extra Tasks'!$Q$3:$Q$40,">=0")),"") | K21: =C21*5-D21*2+IF(E21="",0,IF(E21>=1,10,IF(E21>=0.9,5,0)))+IFERROR(J21,0) -> 0 | L21: =IF($A21="","",IF(K21>=50,"Gold",IF(K21>=30,"Silver",IF(K21>=15,"Bronze","No Reward Yet")))) -> No Reward Yet
A22: Amanpreet | B22: ='Project & Task Tracker'!D20 -> Sales | C22: =IF($A22="",0,COUNTIFS('Project & Task Tracker'!$C$4:$C$56,$A22,'Project & Task Tracker'!$K$4:$K$56,"Yes")+COUNTIFS('Extra Tasks'!$C$3:$C$40,$A22,'Extra Tasks'!$K$3:$K$40,"Yes")) -> 0 | D22: =IF($A22="",0,COUNTIFS('Project & Task Tracker'!$C$4:$C$56,$A22,'Project & Task Tracker'!$J$4:$J$56,"Delayed")+COUNTIFS('Extra Tasks'!$C$3:$C$40,$A22,'Extra Tasks'!$J$3:$J$40,"Delayed")) -> 0 | E22: =IFERROR((SUMIFS('Project & Task Tracker'!$Q$4:$Q$56,'Project & Task Tracker'!$C$4:$C$56,$A22)+SUMIFS('Extra Tasks'!$Q$3:$Q$40,'Extra Tasks'!$C$3:$C$40,$A22))/(COUNTIFS('Project & Task Tracker'!$C$4:$C$56,$A22,'Project & Task Tracker'!$Q$4:$Q$56,">=0")+COUNTIFS('Extra Tasks'!$C$3:$C$40,$A22,'Extra Tasks'!$Q$3:$Q$40,">=0")),"") | K22: =C22*5-D22*2+IF(E22="",0,IF(E22>=1,10,IF(E22>=0.9,5,0)))+IFERROR(J22,0) -> 0 | L22: =IF($A22="","",IF(K22>=50,"Gold",IF(K22>=30,"Silver",IF(K22>=15,"Bronze","No Reward Yet")))) -> No Reward Yet
A23: Satwinder | B23: ='Project & Task Tracker'!D21 -> Sales | C23: =IF($A23="",0,COUNTIFS('Project & Task Tracker'!$C$4:$C$56,$A23,'Project & Task Tracker'!$K$4:$K$56,"Yes")+COUNTIFS('Extra Tasks'!$C$3:$C$40,$A23,'Extra Tasks'!$K$3:$K$40,"Yes")) -> 0 | D23: =IF($A23="",0,COUNTIFS('Project & Task Tracker'!$C$4:$C$56,$A23,'Project & Task Tracker'!$J$4:$J$56,"Delayed")+COUNTIFS('Extra Tasks'!$C$3:$C$40,$A23,'Extra Tasks'!$J$3:$J$40,"Delayed")) -> 0 | E23: =IFERROR((SUMIFS('Project & Task Tracker'!$Q$4:$Q$56,'Project & Task Tracker'!$C$4:$C$56,$A23)+SUMIFS('Extra Tasks'!$Q$3:$Q$40,'Extra Tasks'!$C$3:$C$40,$A23))/(COUNTIFS('Project & Task Tracker'!$C$4:$C$56,$A23,'Project & Task Tracker'!$Q$4:$Q$56,">=0")+COUNTIFS('Extra Tasks'!$C$3:$C$40,$A23,'Extra Tasks'!$Q$3:$Q$40,">=0")),"") | K23: =C23*5-D23*2+IF(E23="",0,IF(E23>=1,10,IF(E23>=0.9,5,0)))+IFERROR(J23,0) -> 0 | L23: =IF($A23="","",IF(K23>=50,"Gold",IF(K23>=30,"Silver",IF(K23>=15,"Bronze","No Reward Yet")))) -> No Reward Yet
A24: Gouri | B24: ='Extra Tasks'!D37 -> Sales | C24: =IF($A24="",0,COUNTIFS('Project & Task Tracker'!$C$4:$C$56,$A24,'Project & Task Tracker'!$K$4:$K$56,"Yes")+COUNTIFS('Extra Tasks'!$C$3:$C$40,$A24,'Extra Tasks'!$K$3:$K$40,"Yes")) -> 0 | D24: =IF($A24="",0,COUNTIFS('Project & Task Tracker'!$C$4:$C$56,$A24,'Project & Task Tracker'!$J$4:$J$56,"Delayed")+COUNTIFS('Extra Tasks'!$C$3:$C$40,$A24,'Extra Tasks'!$J$3:$J$40,"Delayed")) -> 0 | E24: =IFERROR((SUMIFS('Project & Task Tracker'!$Q$4:$Q$56,'Project & Task Tracker'!$C$4:$C$56,$A24)+SUMIFS('Extra Tasks'!$Q$3:$Q$40,'Extra Tasks'!$C$3:$C$40,$A24))/(COUNTIFS('Project & Task Tracker'!$C$4:$C$56,$A24,'Project & Task Tracker'!$Q$4:$Q$56,">=0")+COUNTIFS('Extra Tasks'!$C$3:$C$40,$A24,'Extra Tasks'!$Q$3:$Q$40,">=0")),"") | K24: =C24*5-D24*2+IF(E24="",0,IF(E24>=1,10,IF(E24>=0.9,5,0)))+IFERROR(J24,0) -> 0 | L24: =IF($A24="","",IF(K24>=50,"Gold",IF(K24>=30,"Silver",IF(K24>=15,"Bronze","No Reward Yet")))) -> No Reward Yet
A25: Ashwani | B25: ='Extra Tasks'!D38 -> Sales | C25: =IF($A25="",0,COUNTIFS('Project & Task Tracker'!$C$4:$C$56,$A25,'Project & Task Tracker'!$K$4:$K$56,"Yes")+COUNTIFS('Extra Tasks'!$C$3:$C$40,$A25,'Extra Tasks'!$K$3:$K$40,"Yes")) -> 0 | D25: =IF($A25="",0,COUNTIFS('Project & Task Tracker'!$C$4:$C$56,$A25,'Project & Task Tracker'!$J$4:$J$56,"Delayed")+COUNTIFS('Extra Tasks'!$C$3:$C$40,$A25,'Extra Tasks'!$J$3:$J$40,"Delayed")) -> 0 | E25: =IFERROR((SUMIFS('Project & Task Tracker'!$Q$4:$Q$56,'Project & Task Tracker'!$C$4:$C$56,$A25)+SUMIFS('Extra Tasks'!$Q$3:$Q$40,'Extra Tasks'!$C$3:$C$40,$A25))/(COUNTIFS('Project & Task Tracker'!$C$4:$C$56,$A25,'Project & Task Tracker'!$Q$4:$Q$56,">=0")+COUNTIFS('Extra Tasks'!$C$3:$C$40,$A25,'Extra Tasks'!$Q$3:$Q$40,">=0")),"") | K25: =C25*5-D25*2+IF(E25="",0,IF(E25>=1,10,IF(E25>=0.9,5,0)))+IFERROR(J25,0) -> 0 | L25: =IF($A25="","",IF(K25>=50,"Gold",IF(K25>=30,"Silver",IF(K25>=15,"Bronze","No Reward Yet")))) -> No Reward Yet
A26: Shalini | B26: ='Extra Tasks'!D39 -> Sales | C26: =IF($A26="",0,COUNTIFS('Project & Task Tracker'!$C$4:$C$56,$A26,'Project & Task Tracker'!$K$4:$K$56,"Yes")+COUNTIFS('Extra Tasks'!$C$3:$C$40,$A26,'Extra Tasks'!$K$3:$K$40,"Yes")) -> 0 | D26: =IF($A26="",0,COUNTIFS('Project & Task Tracker'!$C$4:$C$56,$A26,'Project & Task Tracker'!$J$4:$J$56,"Delayed")+COUNTIFS('Extra Tasks'!$C$3:$C$40,$A26,'Extra Tasks'!$J$3:$J$40,"Delayed")) -> 0 | E26: =IFERROR((SUMIFS('Project & Task Tracker'!$Q$4:$Q$56,'Project & Task Tracker'!$C$4:$C$56,$A26)+SUMIFS('Extra Tasks'!$Q$3:$Q$40,'Extra Tasks'!$C$3:$C$40,$A26))/(COUNTIFS('Project & Task Tracker'!$C$4:$C$56,$A26,'Project & Task Tracker'!$Q$4:$Q$56,">=0")+COUNTIFS('Extra Tasks'!$C$3:$C$40,$A26,'Extra Tasks'!$Q$3:$Q$40,">=0")),"") | K26: =C26*5-D26*2+IF(E26="",0,IF(E26>=1,10,IF(E26>=0.9,5,0)))+IFERROR(J26,0) -> 0 | L26: =IF($A26="","",IF(K26>=50,"Gold",IF(K26>=30,"Silver",IF(K26>=15,"Bronze","No Reward Yet")))) -> No Reward Yet
A27: Salamat | B27: ='Project & Task Tracker'!D22 -> Sales | C27: =IF($A27="",0,COUNTIFS('Project & Task Tracker'!$C$4:$C$56,$A27,'Project & Task Tracker'!$K$4:$K$56,"Yes")+COUNTIFS('Extra Tasks'!$C$3:$C$40,$A27,'Extra Tasks'!$K$3:$K$40,"Yes")) -> 0 | D27: =IF($A27="",0,COUNTIFS('Project & Task Tracker'!$C$4:$C$56,$A27,'Project & Task Tracker'!$J$4:$J$56,"Delayed")+COUNTIFS('Extra Tasks'!$C$3:$C$40,$A27,'Extra Tasks'!$J$3:$J$40,"Delayed")) -> 0 | E27: =IFERROR((SUMIFS('Project & Task Tracker'!$Q$4:$Q$56,'Project & Task Tracker'!$C$4:$C$56,$A27)+SUMIFS('Extra Tasks'!$Q$3:$Q$40,'Extra Tasks'!$C$3:$C$40,$A27))/(COUNTIFS('Project & Task Tracker'!$C$4:$C$56,$A27,'Project & Task Tracker'!$Q$4:$Q$56,">=0")+COUNTIFS('Extra Tasks'!$C$3:$C$40,$A27,'Extra Tasks'!$Q$3:$Q$40,">=0")),"") | K27: =C27*5-D27*2+IF(E27="",0,IF(E27>=1,10,IF(E27>=0.9,5,0)))+IFERROR(J27,0) -> 0 | L27: =IF($A27="","",IF(K27>=50,"Gold",IF(K27>=30,"Silver",IF(K27>=15,"Bronze","No Reward Yet")))) -> No Reward Yet
A28: Shivani Sharma | B28: ='Project & Task Tracker'!D23 -> Sales | C28: =IF($A28="",0,COUNTIFS('Project & Task Tracker'!$C$4:$C$56,$A28,'Project & Task Tracker'!$K$4:$K$56,"Yes")+COUNTIFS('Extra Tasks'!$C$3:$C$40,$A28,'Extra Tasks'!$K$3:$K$40,"Yes")) -> 0 | D28: =IF($A28="",0,COUNTIFS('Project & Task Tracker'!$C$4:$C$56,$A28,'Project & Task Tracker'!$J$4:$J$56,"Delayed")+COUNTIFS('Extra Tasks'!$C$3:$C$40,$A28,'Extra Tasks'!$J$3:$J$40,"Delayed")) -> 0 | E28: =IFERROR((SUMIFS('Project & Task Tracker'!$Q$4:$Q$56,'Project & Task Tracker'!$C$4:$C$56,$A28)+SUMIFS('Extra Tasks'!$Q$3:$Q$40,'Extra Tasks'!$C$3:$C$40,$A28))/(COUNTIFS('Project & Task Tracker'!$C$4:$C$56,$A28,'Project & Task Tracker'!$Q$4:$Q$56,">=0")+COUNTIFS('Extra Tasks'!$C$3:$C$40,$A28,'Extra Tasks'!$Q$3:$Q$40,">=0")),"") | K28: =C28*5-D28*2+IF(E28="",0,IF(E28>=1,10,IF(E28>=0.9,5,0)))+IFERROR(J28,0) -> 0 | L28: =IF($A28="","",IF(K28>=50,"Gold",IF(K28>=30,"Silver",IF(K28>=15,"Bronze","No Reward Yet")))) -> No Reward Yet
A29: Shivani Dhiman | B29: ='Project & Task Tracker'!D24 -> Sales | C29: =IF($A29="",0,COUNTIFS('Project & Task Tracker'!$C$4:$C$56,$A29,'Project & Task Tracker'!$K$4:$K$56,"Yes")+COUNTIFS('Extra Tasks'!$C$3:$C$40,$A29,'Extra Tasks'!$K$3:$K$40,"Yes")) -> 0 | D29: =IF($A29="",0,COUNTIFS('Project & Task Tracker'!$C$4:$C$56,$A29,'Project & Task Tracker'!$J$4:$J$56,"Delayed")+COUNTIFS('Extra Tasks'!$C$3:$C$40,$A29,'Extra Tasks'!$J$3:$J$40,"Delayed")) -> 0 | E29: =IFERROR((SUMIFS('Project & Task Tracker'!$Q$4:$Q$56,'Project & Task Tracker'!$C$4:$C$56,$A29)+SUMIFS('Extra Tasks'!$Q$3:$Q$40,'Extra Tasks'!$C$3:$C$40,$A29))/(COUNTIFS('Project & Task Tracker'!$C$4:$C$56,$A29,'Project & Task Tracker'!$Q$4:$Q$56,">=0")+COUNTIFS('Extra Tasks'!$C$3:$C$40,$A29,'Extra Tasks'!$Q$3:$Q$40,">=0")),"") | K29: =C29*5-D29*2+IF(E29="",0,IF(E29>=1,10,IF(E29>=0.9,5,0)))+IFERROR(J29,0) -> 0 | L29: =IF($A29="","",IF(K29>=50,"Gold",IF(K29>=30,"Silver",IF(K29>=15,"Bronze","No Reward Yet")))) -> No Reward Yet
A30: Shubham | B30: ='Project & Task Tracker'!D25 -> Sales | C30: =IF($A30="",0,COUNTIFS('Project & Task Tracker'!$C$4:$C$56,$A30,'Project & Task Tracker'!$K$4:$K$56,"Yes")+COUNTIFS('Extra Tasks'!$C$3:$C$40,$A30,'Extra Tasks'!$K$3:$K$40,"Yes")) -> 0 | D30: =IF($A30="",0,COUNTIFS('Project & Task Tracker'!$C$4:$C$56,$A30,'Project & Task Tracker'!$J$4:$J$56,"Delayed")+COUNTIFS('Extra Tasks'!$C$3:$C$40,$A30,'Extra Tasks'!$J$3:$J$40,"Delayed")) -> 0 | E30: =IFERROR((SUMIFS('Project & Task Tracker'!$Q$4:$Q$56,'Project & Task Tracker'!$C$4:$C$56,$A30)+SUMIFS('Extra Tasks'!$Q$3:$Q$40,'Extra Tasks'!$C$3:$C$40,$A30))/(COUNTIFS('Project & Task Tracker'!$C$4:$C$56,$A30,'Project & Task Tracker'!$Q$4:$Q$56,">=0")+COUNTIFS('Extra Tasks'!$C$3:$C$40,$A30,'Extra Tasks'!$Q$3:$Q$40,">=0")),"") | K30: =C30*5-D30*2+IF(E30="",0,IF(E30>=1,10,IF(E30>=0.9,5,0)))+IFERROR(J30,0) -> 0 | L30: =IF($A30="","",IF(K30>=50,"Gold",IF(K30>=30,"Silver",IF(K30>=15,"Bronze","No Reward Yet")))) -> No Reward Yet
A31: Simar | B31: ='Project & Task Tracker'!D26 -> Sales | C31: =IF($A31="",0,COUNTIFS('Project & Task Tracker'!$C$4:$C$56,$A31,'Project & Task Tracker'!$K$4:$K$56,"Yes")+COUNTIFS('Extra Tasks'!$C$3:$C$40,$A31,'Extra Tasks'!$K$3:$K$40,"Yes")) -> 0 | D31: =IF($A31="",0,COUNTIFS('Project & Task Tracker'!$C$4:$C$56,$A31,'Project & Task Tracker'!$J$4:$J$56,"Delayed")+COUNTIFS('Extra Tasks'!$C$3:$C$40,$A31,'Extra Tasks'!$J$3:$J$40,"Delayed")) -> 0 | E31: =IFERROR((SUMIFS('Project & Task Tracker'!$Q$4:$Q$56,'Project & Task Tracker'!$C$4:$C$56,$A31)+SUMIFS('Extra Tasks'!$Q$3:$Q$40,'Extra Tasks'!$C$3:$C$40,$A31))/(COUNTIFS('Project & Task Tracker'!$C$4:$C$56,$A31,'Project & Task Tracker'!$Q$4:$Q$56,">=0")+COUNTIFS('Extra Tasks'!$C$3:$C$40,$A31,'Extra Tasks'!$Q$3:$Q$40,">=0")),"") | K31: =C31*5-D31*2+IF(E31="",0,IF(E31>=1,10,IF(E31>=0.9,5,0)))+IFERROR(J31,0) -> 0 | L31: =IF($A31="","",IF(K31>=50,"Gold",IF(K31>=30,"Silver",IF(K31>=15,"Bronze","No Reward Yet")))) -> No Reward Yet
A32: Anita | B32: ='Project & Task Tracker'!D27 -> Sales | C32: =IF($A32="",0,COUNTIFS('Project & Task Tracker'!$C$4:$C$56,$A32,'Project & Task Tracker'!$K$4:$K$56,"Yes")+COUNTIFS('Extra Tasks'!$C$3:$C$40,$A32,'Extra Tasks'!$K$3:$K$40,"Yes")) -> 0 | D32: =IF($A32="",0,COUNTIFS('Project & Task Tracker'!$C$4:$C$56,$A32,'Project & Task Tracker'!$J$4:$J$56,"Delayed")+COUNTIFS('Extra Tasks'!$C$3:$C$40,$A32,'Extra Tasks'!$J$3:$J$40,"Delayed")) -> 0 | E32: =IFERROR((SUMIFS('Project & Task Tracker'!$Q$4:$Q$56,'Project & Task Tracker'!$C$4:$C$56,$A32)+SUMIFS('Extra Tasks'!$Q$3:$Q$40,'Extra Tasks'!$C$3:$C$40,$A32))/(COUNTIFS('Project & Task Tracker'!$C$4:$C$56,$A32,'Project & Task Tracker'!$Q$4:$Q$56,">=0")+COUNTIFS('Extra Tasks'!$C$3:$C$40,$A32,'Extra Tasks'!$Q$3:$Q$40,">=0")),"") | K32: =C32*5-D32*2+IF(E32="",0,IF(E32>=1,10,IF(E32>=0.9,5,0)))+IFERROR(J32,0) -> 0 | L32: =IF($A32="","",IF(K32>=50,"Gold",IF(K32>=30,"Silver",IF(K32>=15,"Bronze","No Reward Yet")))) -> No Reward Yet
A33: Amit | B33: ='Project & Task Tracker'!D28 -> Sales | C33: =IF($A33="",0,COUNTIFS('Project & Task Tracker'!$C$4:$C$56,$A33,'Project & Task Tracker'!$K$4:$K$56,"Yes")+COUNTIFS('Extra Tasks'!$C$3:$C$40,$A33,'Extra Tasks'!$K$3:$K$40,"Yes")) -> 0 | D33: =IF($A33="",0,COUNTIFS('Project & Task Tracker'!$C$4:$C$56,$A33,'Project & Task Tracker'!$J$4:$J$56,"Delayed")+COUNTIFS('Extra Tasks'!$C$3:$C$40,$A33,'Extra Tasks'!$J$3:$J$40,"Delayed")) -> 0 | E33: =IFERROR((SUMIFS('Project & Task Tracker'!$Q$4:$Q$56,'Project & Task Tracker'!$C$4:$C$56,$A33)+SUMIFS('Extra Tasks'!$Q$3:$Q$40,'Extra Tasks'!$C$3:$C$40,$A33))/(COUNTIFS('Project & Task Tracker'!$C$4:$C$56,$A33,'Project & Task Tracker'!$Q$4:$Q$56,">=0")+COUNTIFS('Extra Tasks'!$C$3:$C$40,$A33,'Extra Tasks'!$Q$3:$Q$40,">=0")),"") | K33: =C33*5-D33*2+IF(E33="",0,IF(E33>=1,10,IF(E33>=0.9,5,0)))+IFERROR(J33,0) -> 0 | L33: =IF($A33="","",IF(K33>=50,"Gold",IF(K33>=30,"Silver",IF(K33>=15,"Bronze","No Reward Yet")))) -> No Reward Yet

Sheet Dashboard
B2: TEAM & PROJECT DASHBOARD
B3: Live — updates automatically from the other 3 sheets
B5: Total Tasks | C5: Ongoing | D5: Completed | E5: Delayed
B6: =COUNTA('Project & Task Tracker'!A4:A56)+COUNTA('Extra Tasks'!A3:A40) -> 91 | C6: =COUNTIF('Project & Task Tracker'!J4:J56,"Ongoing")+COUNTIF('Extra Tasks'!J3:J40,"Ongoing") -> 2 | D6: =COUNTIF('Project & Task Tracker'!J4:J56,"Completed")+COUNTIF('Extra Tasks'!J3:J40,"Completed") -> 9 | E6: =COUNTIF('Project & Task Tracker'!J4:J56,"Delayed")+COUNTIF('Extra Tasks'!J3:J40,"Delayed") -> 0
B9: Task Status | C9: Count | E9: Team | F9: Open Tasks
B10: Ongoing | C10: =COUNTIF('Project & Task Tracker'!J4:J56,"Ongoing")+COUNTIF('Extra Tasks'!J3:J40,"Ongoing") -> 2 | E10: Learning & Development | F10: =COUNTIFS('Project & Task Tracker'!$D$4:$D$56,$E10,'Project & Task Tracker'!$J$4:$J$56,"<>Completed")+COUNTIFS('Extra Tasks'!$D$3:$D$40,$E10,'Extra Tasks'!$J$3:$J$40,"<>Completed") -> 0
B11: Completed | C11: =COUNTIF('Project & Task Tracker'!J4:J56,"Completed")+COUNTIF('Extra Tasks'!J3:J40,"Completed") -> 9 | E11: Human Resources | F11: =COUNTIFS('Project & Task Tracker'!$D$4:$D$56,$E11,'Project & Task Tracker'!$J$4:$J$56,"<>Completed")+COUNTIFS('Extra Tasks'!$D$3:$D$40,$E11,'Extra Tasks'!$J$3:$J$40,"<>Completed") -> 0
B12: Delayed | C12: =COUNTIF('Project & Task Tracker'!J4:J56,"Delayed")+COUNTIF('Extra Tasks'!J3:J40,"Delayed") -> 0 | E12: IT / Tech | F12: =COUNTIFS('Project & Task Tracker'!$D$4:$D$56,$E12,'Project & Task Tracker'!$J$4:$J$56,"<>Completed")+COUNTIFS('Extra Tasks'!$D$3:$D$40,$E12,'Extra Tasks'!$J$3:$J$40,"<>Completed") -> 0
B13: On Hold | C13: =COUNTIF('Project & Task Tracker'!J4:J56,"On Hold")+COUNTIF('Extra Tasks'!J3:J40,"On Hold") -> 0 | E13: Sales | F13: =COUNTIFS('Project & Task Tracker'!$D$4:$D$56,$E13,'Project & Task Tracker'!$J$4:$J$56,"<>Completed")+COUNTIFS('Extra Tasks'!$D$3:$D$40,$E13,'Extra Tasks'!$J$3:$J$40,"<>Completed") -> 82
E14: Operations | F14: =COUNTIFS('Project & Task Tracker'!$D$4:$D$56,$E14,'Project & Task Tracker'!$J$4:$J$56,"<>Completed")+COUNTIFS('Extra Tasks'!$D$3:$D$40,$E14,'Extra Tasks'!$J$3:$J$40,"<>Completed") -> 0
E15: Compliance | F15: =COUNTIFS('Project & Task Tracker'!$D$4:$D$56,$E15,'Project & Task Tracker'!$J$4:$J$56,"<>Completed")+COUNTIFS('Extra Tasks'!$D$3:$D$40,$E15,'Extra Tasks'!$J$3:$J$40,"<>Completed") -> 0
E16: Customer Support | F16: =COUNTIFS('Project & Task Tracker'!$D$4:$D$56,$E16,'Project & Task Tracker'!$J$4:$J$56,"<>Completed")+COUNTIFS('Extra Tasks'!$D$3:$D$40,$E16,'Extra Tasks'!$J$3:$J$40,"<>Completed") -> 0
E17: Finance | F17: =COUNTIFS('Project & Task Tracker'!$D$4:$D$56,$E17,'Project & Task Tracker'!$J$4:$J$56,"<>Completed")+COUNTIFS('Extra Tasks'!$D$3:$D$40,$E17,'Extra Tasks'!$J$3:$J$40,"<>Completed") -> 0
B21: REWARDS SNAPSHOT
B22: Gold | C22: =COUNTIF('Rewards & Recognition'!L4:L33,"Gold") -> 0
B23: Silver | C23: =COUNTIF('Rewards & Recognition'!L4:L33,"Silver") -> 0
B24: Bronze | C24: =COUNTIF('Rewards & Recognition'!L4:L33,"Bronze") -> 0

Sheet Extra Tasks
A2: Project / Initiative | B2: Task / Deliverable | C2: Team Member | D2: Team | E2: Champion / Owner | F2: Priority | G2: Start Date | H2: Target Date | I2: Completed Date | J2: Status | K2: On Time? (auto) | L2: Delay Reason | M2: Delay Reason Validated? | N2: Remarks | O2: Monthly Individual Target (Number) | P2: Monthly Achieved (Number) | Q2: Achievement % (auto)
A3: Sales Performance | B3: Backstage, Hold, Chat, Star ticket etc other tasks completion on daily basis | C3: Sakshi | D3: Sales | E3: Rajesh | F3: High | G3: 46266 | H3: 46295 | K3: =IF(I3="","",IF(I3<=H3,"Yes","No")) | O3: Update within within TAT Star (within hour) same day | Q3: =IFERROR(IF(OR(O3="",O3=0),"",P3/O3),"")
A4: Sales Performance | B4: Team Audit | C4: Sakshi | D4: Sales | E4: Rajesh | F4: High | G4: 46266 | H4: 46295 | K4: =IF(I4="","",IF(I4<=H4,"Yes","No")) | O4: Monthly | Q4: =IFERROR(IF(OR(O4="",O4=0),"",P4/O4),"")
A5: Sales Performance | B5: Team Tasks Audit | C5: Rajesh | D5: Sales | E5: Gurjot Sodhi | F5: High | G5: 46266 | H5: 46295 | K5: =IF(I5="","",IF(I5<=H5,"Yes","No")) | Q5: =IFERROR(IF(OR(O5="",O5=0),"",P5/O5),"")
A6: Sales Performance | B6: Daily & Monthly Tasks & Report Updation | C6: Rajesh | D6: Sales | E6: Gurjot Sodhi | F6: High | G6: 46266 | H6: 46295 | K6: =IF(I6="","",IF(I6<=H6,"Yes","No")) | Q6: =IFERROR(IF(OR(O6="",O6=0),"",P6/O6),"")
A7: Sales Performance | B7: Internal & External Meetings | C7: Rajesh | D7: Sales | E7: Gurjot Sodhi | F7: High | G7: 46266 | H7: 46295 | K7: =IF(I7="","",IF(I7<=H7,"Yes","No")) | Q7: =IFERROR(IF(OR(O7="",O7=0),"",P7/O7),"")
A8: Sales Performance | B8: Requirements Through Jira | C8: Rajesh | D8: Sales | E8: Gurjot Sodhi | F8: High | G8: 46266 | H8: 46295 | K8: =IF(I8="","",IF(I8<=H8,"Yes","No")) | Q8: =IFERROR(IF(OR(O8="",O8=0),"",P8/O8),"")
A9: Sales Performance | B9: Onboarding & Other Enhancements | C9: Rajesh | D9: Sales | E9: Gurjot Sodhi | F9: High | G9: 46266 | H9: 46295 | K9: =IF(I9="","",IF(I9<=H9,"Yes","No")) | Q9: =IFERROR(IF(OR(O9="",O9=0),"",P9/O9),"")
A10: Sales Performance | B10: Testing & Feedback Etc | C10: Rajesh | D10: Sales | E10: Gurjot Sodhi | F10: High | G10: 46266 | H10: 46295 | K10: =IF(I10="","",IF(I10<=H10,"Yes","No")) | Q10: =IFERROR(IF(OR(O10="",O10=0),"",P10/O10),"")
A11: Sales Performance | B11: Non-Individual Account Opening Conversion | C11: Durga | D11: Sales | E11: Gurjot Sodhi | F11: High | G11: 46266 | H11: 46295 | K11: =IF(I11="","",IF(I11<=H11,"Yes","No")) | Q11: =IFERROR(IF(OR(O11="",O11=0),"",P11/O11),"")
A12: Sales Performance | B12: Fund Mobilisation from Existing Active Non-Individual Clients – Daily checking by Back Office | C12: Durga | D12: Sales | E12: Gurjot Sodhi | F12: High | G12: 46266 | H12: 46295 | K12: =IF(I12="","",IF(I12<=H12,"Yes","No")) | Q12: =IFERROR(IF(OR(O12="",O12=0),"",P12/O12),"")
A13: Sales Performance | B13: New AP Onboarding (Acquire and successfully onboard new Authorized Partners by completing documentation, activation, and training processes within the defined timelines. | C13: Durga | D13: Sales | E13: Gurjot Sodhi | F13: Medium | G13: 46266 | H13: 46295 | K13: =IF(I13="","",IF(I13<=H13,"Yes","No")) | Q13: =IFERROR(IF(OR(O13="",O13=0),"",P13/O13),"")
A14: Sales Performance | B14: Lead-to-Registration Conversion Performance (Team) | C14: Durga | D14: Sales | E14: Gurjot Sodhi | F14: Medium | G14: 46266 | H14: 46295 | K14: =IF(I14="","",IF(I14<=H14,"Yes","No")) | Q14: =IFERROR(IF(OR(O14="",O14=0),"",P14/O14),"")
A15: Sales Performance | B15: Team Productivity & Target Achievement (Drive timely achievement of team targets by enhancing overall productivity through performance tracking, gap analysis, and strong accountability.) | C15: Durga | D15: Sales | E15: Gurjot Sodhi | F15: High | G15: 46266 | H15: 46295 | K15: =IF(I15="","",IF(I15<=H15,"Yes","No")) | Q15: =IFERROR(IF(OR(O15="",O15=0),"",P15/O15),"")
A16: Sales Performance | B16: Daily & Monthly Tasks & Report Updation | C16: Durga | D16: Sales | E16: Gurjot Sodhi | F16: High | G16: 46266 | H16: 46295 | K16: =IF(I16="","",IF(I16<=H16,"Yes","No")) | Q16: =IFERROR(IF(OR(O16="",O16=0),"",P16/O16),"")
... A40: Sales Performance | B40: Reception Tasks Are Being Handled Efficiently | C40: Ramandeep | D40: Sales | E40: Rajesh | F40: Medium | G40: 46266 | H40: 46295 | K40: =IF(I40="","",IF(I40<=H40,"Yes","No")) | Q40: =IFERROR(IF(OR(O40="",O40=0),"",P40/O40),"")
