Workbook

Sheet README
A1: Finvasia PT-R&R Platform - Corrected Source Data
A2: Prepared 29-Sep-2026, extended 08-Oct-2026, from: Organizational_Chart (23-Aug-26), Project_Tracker (Rest, Shoonya), R_R_Parameters_2, RACI, RCA
A4: As-of date used for overdue checks | B4: 46294
A6: Sheet | B6: What it contains
A7: Employee_Master | B7: Every box from the 17 visible org-chart sheets as one row. Proposed record IDs (EMP-/POS-), cleaned name and designation, reporting manager, proposed login role, and data-quality flags. The 2 hidden sheets (Prodduct, Product-Shoonya) are outdated copies and were NOT imported.
A8: Name_Collisions | B8: Names shared by more than one record. Each must be confirmed against HRMS before import.
A9: Departments | B9: Canonical department list, head, live headcount, proposed performance category, and the tracker aliases that map to it.
A10: Category_Weights | B10: Corrected metric weights per team category. Every column must total 100% (check row).
A11: Tracker_Cleaned | B11: Original 115 tracker rows split to one row per task x assignee, with resolved Employee IDs, mapped statuses, classified blockers and derived timing (formulas).
A12: Project_Register | B12: One row per project with proposed PRJ IDs and live task counts.
A13: OnTime_Recalc | B13: On-time rate recalculated with the corrected eligibility rules, beside the value the old sheet produced.
A14: Issue_Register | B14: Every issue found in the five source files, with severity and the fix applied.
A15: Workflow_Templates | B15: RACI.xlsx turned into a reusable "Email campaign" project template: one row per step with R / A / C / I, checklist, reviewer, required evidence, SLA in business days and effort. Conflicts between the two versions in the source are flagged.
A16: Risk_Register | B16: Risks from RACI.xlsx, one per row, linked to the template step, with criticality, dependencies, assumptions, mitigation and new owner / status / review-date fields.
A17: RCA_Register | B17: Incident root-cause log built from RCA.xlsx (which had headers only). Fill one row per incident; grey columns are formulas. Header comments show which source column each field came from. Row 2 is an example to replace or delete.
... A20: ID note | B20: EMP-/POS-/PRJ- IDs are placeholders so the data can be linked now. Replace EMP IDs with official HRMS employee codes before go-live; the HRMS column is provided for that.

Sheet Employee_Master
A1: Record ID | B1: HRMS Emp Code (fill) | C1: Record Type | D1: Full Name | E1: Designation | F1: Department | G1: Level in Chart | H1: Reporting Manager ID | I1: Reporting Manager | J1: Direct Reports | K1: Proposed Platform Role | L1: Flags / To Confirm | M1: Original Chart Text
A2: POS-0001 | C2: Vacant Position | D2: (vacant) | E2: Managing Director | F2: AI | G2: 1 | J2: =COUNTIF($H$2:$H$326,A2) -> 7 | K2: None (vacant) | L2: Vacant / unnamed position | M2: Managing Director
A3: EMP-0002 | C3: Employee | D3: Anudesh Saini | E3: Machine Learning Engineer | F3: AI | G3: 2 | H3: POS-0001 | I3: Managing Director | J3: =COUNTIF($H$2:$H$326,A3) -> 4 | K3: Manager | M3: Anudesh Saini (Machine Learning Engineer)
A4: EMP-0003 | C4: Employee | D4: Mukund Madhav | E4: Data Engineer | F4: AI | G4: 3 | H4: EMP-0002 | I4: Anudesh Saini | J4: =COUNTIF($H$2:$H$326,A4) -> 1 | K4: Manager | M4: Mukund Madhav (Data Engineer)
A5: EMP-0004 | C5: Employee | D5: Piyush Chhabra | E5: Data Engineer | F5: AI | G5: 4 | H5: EMP-0003 | I5: Mukund Madhav | J5: =COUNTIF($H$2:$H$326,A5) -> 0 | K5: None (employee record) | M5: Piyush Chhabra (Data Engineer)
A6: EMP-0005 | C6: Employee | D6: Chetan Sharma | E6: AI Engineer | F6: AI | G6: 3 | H6: EMP-0002 | I6: Anudesh Saini | J6: =COUNTIF($H$2:$H$326,A6) -> 2 | K6: Manager | M6: Chetan Sharma (AI Engineer)
A7: EMP-0006 | C7: Employee | D7: Divyanshu | E7: Jr. ML Ops Engineer | F7: AI | G7: 4 | H7: EMP-0005 | I7: Chetan Sharma | J7: =COUNTIF($H$2:$H$326,A7) -> 0 | K7: None (employee record) | L7: Single name only - add surname | M7: Divyanshu (Jr. ML Ops Engineer)
A8: EMP-0007 | C8: Employee | D8: Nikhal Kumar Rana | E8: Associate AI Engineer | F8: AI | G8: 4 | H8: EMP-0005 | I8: Chetan Sharma | J8: =COUNTIF($H$2:$H$326,A8) -> 0 | K8: None (employee record) | M8: Nikhal Kumar Rana (Associate AI Engineer)
A9: EMP-0008 | C9: Employee | D9: Ankit Sharma | E9: Data Analyst | F9: AI | G9: 3 | H9: EMP-0002 | I9: Anudesh Saini | J9: =COUNTIF($H$2:$H$326,A9) -> 0 | K9: None (employee record) | M9: Ankit Sharma (Data Analyst)
A10: EMP-0009 | C10: Employee | D10: Rajat Sharma | E10: Sr. AI Engineer | F10: AI | G10: 3 | H10: EMP-0002 | I10: Anudesh Saini | J10: =COUNTIF($H$2:$H$326,A10) -> 3 | K10: Manager | M10: Rajat Sharma (Sr. AI Engineer)
A11: EMP-0010 | C11: Employee | D11: Sameep Rohilla | E11: Jr. AI Engineer | F11: AI | G11: 4 | H11: EMP-0009 | I11: Rajat Sharma | J11: =COUNTIF($H$2:$H$326,A11) -> 0 | K11: None (employee record) | M11: Sameep Rohilla (Jr. AI Engineer)
A12: EMP-0011 | C12: Employee | D12: Ishan Singla | E12: Jr. ML Ops Engineer | F12: AI | G12: 4 | H12: EMP-0009 | I12: Rajat Sharma | J12: =COUNTIF($H$2:$H$326,A12) -> 0 | K12: None (employee record) | M12: Ishan Singla (Jr. ML Ops Engineer)
A13: EMP-0012 | C13: Employee | D13: Kunal Mehra | E13: Jr. AI Engineer | F13: AI | G13: 4 | H13: EMP-0009 | I13: Rajat Sharma | J13: =COUNTIF($H$2:$H$326,A13) -> 0 | K13: None (employee record) | M13: Kunal Mehra (Jr. AI Engineer)
A14: POS-0001 | C14: Vacant Position | D14: (vacant) | E14: Managing Director | F14: Product | G14: 1 | J14: =COUNTIF($H$2:$H$326,A14) -> 7 | K14: None (vacant) | L14: Vacant / unnamed position | M14: Managing Director
A15: EMP-0014 | C15: Employee | D15: Vishal Sharma | E15: Lead QA | F15: Product | G15: 2 | H15: POS-0001 | I15: Managing Director | J15: =COUNTIF($H$2:$H$326,A15) -> 1 | K15: Team Lead | M15: Vishal Sharma (Lead QA)
A16: EMP-0015 | C16: Employee | D16: Amit Kumar | E16: Sr. QA Engineer | F16: Product | G16: 3 | H16: EMP-0014 | I16: Vishal Sharma | J16: =COUNTIF($H$2:$H$326,A16) -> 4 | K16: Manager | L16: Name shared with another record - confirm identity | M16: Amit Kumar (Sr. QA Engineer)
A17: EMP-0016 | C17: Employee | D17: Pankaj Kumar | E17: QA Engineer | F17: Product | G17: 4 | H17: EMP-0015 | I17: Amit Kumar | J17: =COUNTIF($H$2:$H$326,A17) -> 0 | K17: None (employee record) | M17: Pankaj Kumar (QA Engineer)
A18: EMP-0017 | C18: Employee | D18: Deepti Sharma | E18: QA Engineer | F18: Product | G18: 4 | H18: EMP-0015 | I18: Amit Kumar | J18: =COUNTIF($H$2:$H$326,A18) -> 0 | K18: None (employee record) | M18: Deepti Sharma (QA Engineer)
A19: EMP-0018 | C19: Employee | D19: Navdeep Thakur | E19: QA Engineer | F19: Product | G19: 4 | H19: EMP-0015 | I19: Amit Kumar | J19: =COUNTIF($H$2:$H$326,A19) -> 0 | K19: None (employee record) | M19: Navdeep Thakur (QA Engineer)
A20: EMP-0019 | C20: Employee | D20: Vipul Mahajan | E20: QA Engineer | F20: Product | G20: 4 | H20: EMP-0015 | I20: Amit Kumar | J20: =COUNTIF($H$2:$H$326,A20) -> 0 | K20: None (employee record) | M20: Vipul Mahajan (QA Engineer)
A21: EMP-0020 | C21: Employee | D21: Deepinder Singh | E21: Sr. Project Manager | F21: Product | G21: 2 | H21: POS-0001 | I21: Managing Director | J21: =COUNTIF($H$2:$H$326,A21) -> 16 | K21: Manager | M21: Deepinder Singh (Sr. Project Manager)
A22: EMP-0021 | C22: Employee | D22: Rajan Kumar | E22: Project Manager | F22: Product | G22: 3 | H22: EMP-0020 | I22: Deepinder Singh | J22: =COUNTIF($H$2:$H$326,A22) -> 1 | K22: Manager | M22: Rajan Kumar (Project Manager)
A23: EMP-0022 | C23: Employee | D23: Geetankshi | E23: Associate Project Coordinator | F23: Product | G23: 4 | H23: EMP-0021 | I23: Rajan Kumar | J23: =COUNTIF($H$2:$H$326,A23) -> 0 | K23: None (employee record) | L23: Single name only - add surname | M23: Geetankshi (Associate Project coordinater)
A24: EMP-0023 | C24: Employee | D24: Sparsh Choudhary | E24: Sr. Software Engineer | F24: Product | G24: 3 | H24: EMP-0020 | I24: Deepinder Singh | J24: =COUNTIF($H$2:$H$326,A24) -> 0 | K24: None (employee record) | M24: Sparsh Choudhary (Sr. Software Engineer)
A25: EMP-0024 | C25: Employee | D25: Sumit Roy | E25: Associate Product Manager | F25: Product | G25: 3 | H25: EMP-0020 | I25: Deepinder Singh | J25: =COUNTIF($H$2:$H$326,A25) -> 5 | K25: Manager | M25: Sumit Roy (Associate Product Manager)
A26: EMP-0025 | C26: Employee | D26: Manisha Kumari | E26: Business Analyst | F26: Product | G26: 4 | H26: EMP-0024 | I26: Sumit Roy | J26: =COUNTIF($H$2:$H$326,A26) -> 0 | K26: None (employee record) | M26: Manisha Kumari (Business Analyst)
A27: EMP-0026 | C27: Employee | D27: Sukriti | E27: Business Analyst | F27: Product | G27: 4 | H27: EMP-0024 | I27: Sumit Roy | J27: =COUNTIF($H$2:$H$326,A27) -> 0 | K27: None (employee record) | L27: Single name only - add surname | M27: Sukriti (Business Analyst)
A28: EMP-0027 | C28: Employee | D28: Aryan Raj | E28: Business Analyst | F28: Product | G28: 4 | H28: EMP-0024 | I28: Sumit Roy | J28: =COUNTIF($H$2:$H$326,A28) -> 0 | K28: None (employee record) | M28: Aryan Raj (Business Analyst)
A29: EMP-0028 | C29: Employee | D29: Siddhant Sharma | E29: Team Lead-API | F29: Product | G29: 4 | H29: EMP-0024 | I29: Sumit Roy | J29: =COUNTIF($H$2:$H$326,A29) -> 0 | K29: None (employee record) | M29: Siddhant Sharma (Team Lead-API)
A30: EMP-0029 | C30: Employee | D30: Saurav Sharma | E30: API Integration Analyst | F30: Product | G30: 4 | H30: EMP-0024 | I30: Sumit Roy | J30: =COUNTIF($H$2:$H$326,A30) -> 2 | K30: Manager | M30: Saurav Sharma (API Integration Analyst)
A31: EMP-0030 | C31: Employee | D31: Avinash Rai | E31: API Support & Tech. Analyst | F31: Product | G31: 5 | H31: EMP-0029 | I31: Saurav Sharma | J31: =COUNTIF($H$2:$H$326,A31) -> 0 | K31: None (employee record) | L31: Chart text malformed (fixed) | M31: Avinash Rai (API Support & Tech. Analyst))
A32: EMP-0031 | C32: Employee | D32: Ashok Sharma | E32: API Support & Tech. Analyst | F32: Product | G32: 5 | H32: EMP-0029 | I32: Saurav Sharma | J32: =COUNTIF($H$2:$H$326,A32) -> 0 | K32: None (employee record) | L32: Chart text malformed (fixed) | M32: Ashok Sharma (API Support & Tech. Analyst))
A33: EMP-0032 | C33: Employee | D33: Ravi Beniwal | E33: Software Engineer | F33: Product | G33: 3 | H33: EMP-0020 | I33: Deepinder Singh | J33: =COUNTIF($H$2:$H$326,A33) -> 0 | K33: None (employee record) | M33: Ravi Beniwal (Software Engineer)
A34: EMP-0033 | C34: Employee | D34: Rakhi | E34: Sr. Software Engineer | F34: Product | G34: 3 | H34: EMP-0020 | I34: Deepinder Singh | J34: =COUNTIF($H$2:$H$326,A34) -> 0 | K34: None (employee record) | L34: Single name only - add surname | M34: Rakhi (Sr. Software Engineer)
A35: EMP-0034 | C35: Employee | D35: Lucky Bawa | E35: Sr. Software Engineer | F35: Product | G35: 3 | H35: EMP-0020 | I35: Deepinder Singh | J35: =COUNTIF($H$2:$H$326,A35) -> 0 | K35: None (employee record) | M35: Lucky Bawa (Sr. Software Engineer)
A36: EMP-0035 | C36: Employee | D36: Virendra Nishad | E36: Software Engineer | F36: Product | G36: 3 | H36: EMP-0020 | I36: Deepinder Singh | J36: =COUNTIF($H$2:$H$326,A36) -> 0 | K36: None (employee record) | M36: Virendra Nishad (Software Engineer)
A37: EMP-0036 | C37: Employee | D37: Pawan Kumar | E37: Software Engineer | F37: Product | G37: 3 | H37: EMP-0020 | I37: Deepinder Singh | J37: =COUNTIF($H$2:$H$326,A37) -> 0 | K37: None (employee record) | L37: Name shared with another record - confirm identity | M37: Pawan Kumar (Sofwtare Engineer)
A38: EMP-0037 | C38: Employee | D38: Ankush | E38: Sr. Software Engineer | F38: Product | G38: 3 | H38: EMP-0020 | I38: Deepinder Singh | J38: =COUNTIF($H$2:$H$326,A38) -> 0 | K38: None (employee record) | L38: Single name only - add surname | M38: Ankush (Sr. Software Engineer)
A39: EMP-0038 | C39: Employee | D39: Muskan | E39: Software Engineer | F39: Product | G39: 3 | H39: EMP-0020 | I39: Deepinder Singh | J39: =COUNTIF($H$2:$H$326,A39) -> 0 | K39: None (employee record) | L39: Name shared with another record - confirm identity; Single name only - add surname | M39: Muskan (Sofwate Engineer)
A40: EMP-0039 | C40: Employee | D40: Avinash | E40: Software Engineer | F40: Product | G40: 3 | H40: EMP-0020 | I40: Deepinder Singh | J40: =COUNTIF($H$2:$H$326,A40) -> 0 | K40: None (employee record) | L40: Single name only - add surname | M40: Avinash (Software Engineer)
...

Sheet Name_Collisions
A1: Name | B1: Record ID | C1: Designation | D1: Department | E1: Reporting Manager | F1: Likely same person? | G1: Resolution (fill)
A2: Amit Kumar | B2: EMP-0015 | C2: Sr. QA Engineer | D2: Product | E2: Vishal Sharma | F2: No - different role/department
A3: Amit Kumar | B3: EMP-0266 | C3: Manager | D3: Sales | E3: Gurjot Singh | F3: No - different role/department
A4: Amritpal Singh | B4: EMP-0240 | C4: CS Executive | D4: Client Support | E4: Neeru Arya | F4: Possibly duplicate entry
A5: Amritpal Singh | B5: EMP-0252 | C5: CS Executive | D5: Client Support | E5: Angel Sharma | F5: Possibly duplicate entry
A6: Ankit | B6: EMP-0041 | C6: Software Engineer | D6: Product | E6: Deepinder Singh | F6: No - different role/department
A7: Ankit | B7: EMP-0223 | C7: CS Executive | D7: Client Support | E7: Ramandeep Kaur | F7: No - different role/department
A8: Gurpreet Singh | B8: EMP-0071 | C8: Project Lead | D8: Product | E8: Parvinder Singh Chopra | F8: No - different role/department
A9: Gurpreet Singh | B9: EMP-0161 | C9: Manager | D9: IT | E9: Patel Rajesh | F9: No - different role/department
A10: Hardeep Singh | B10: EMP-0198 | C10: AM Compliance | D10: Compliance | E10: Akanksha Chhabra | F10: No - different role/department
A11: Hardeep Singh | B11: EMP-0250 | C11: CS Executive | D11: Client Support | E11: Angel Sharma | F11: No - different role/department
A12: Jitender Thakur | B12: EMP-0094 | C12: TA | D12: HR | E12: Himani Sharma | F12: No - different role/department
A13: Jitender Thakur | B13: EMP-0179 | C13: BO Executive | D13: Operations & BO | E13: Kanav Verma | F13: No - different role/department
... A24: Pawan Kumar | B24: EMP-0036 | C24: Software Engineer | D24: Product | E24: Deepinder Singh | F24: No - different role/department
A25: Pawan Kumar | B25: EMP-0109 | C25: AVP-Operations | D25: Demat | F25: No - different role/department
A26: Pawan Kumar | B26: EMP-0109 | C26: AVP-Operations | D26: Operations & BO | F26: No - different role/department
A27: Pawan Kumar | B27: EMP-0109 | C27: AVP-Operations | D27: Compliance | F27: No - different role/department
A28: Rajesh Kumar | B28: EMP-0155 | C28: Sr. SEO Specialist | D28: Digital Marketing | E28: Ramneek | F28: No - different role/department
A29: Rajesh Kumar | B29: EMP-0280 | C29: Sr. Manager | D29: Sales | E29: Gurjot Singh | F29: No - different role/department
A30: Ramandeep Kaur | B30: EMP-0222 | C30: Sr. CS Executive | D30: Client Support | E30: Sahil Sharma | F30: No - different role/department
A31: Ramandeep Kaur | B31: EMP-0283 | C31: Sales Executive | D31: Sales | E31: Sakshi Sharma | F31: No - different role/department
A32: Sakshi Sharma | B32: EMP-0258 | C32: CS Executive | D32: jUMPP CS & Sales | E32: Priyanka Rana | F32: No - different role/department
A33: Sakshi Sharma | B33: EMP-0281 | C33: Team Lead | D33: Sales | E33: Rajesh Kumar | F33: No - different role/department
A34: Salim Khan | B34: EMP-0206 | C34: RMS Executive | D34: RMS & Dealer | E34: Naveen Kumar | F34: Possibly duplicate entry
A35: Salim Khan | B35: EMP-0208 | C35: RMS Executive | D35: RMS & Dealer | E35: Naveen Kumar | F35: Possibly duplicate entry

Sheet Departments
A1: Department | B1: Head Record ID | C1: Head | D1: Headcount (employees) | E1: Vacant Positions | F1: Proposed Category | G1: Tracker Name Aliases | H1: Notes
A2: Sales | B2: EMP-0265 | C2: Gurjot Singh | D2: =COUNTIFS(Employee_Master!$F:$F,A2,Employee_Master!$C:$C,"Employee") -> 37 | E2: =COUNTIFS(Employee_Master!$F:$F,A2,Employee_Master!$C:$C,"Vacant Position") -> 0 | F2: Core Revenue | G2: Sales | H2: Direct revenue targets.
A3: Insurance | B3: POS-0310 | C3: Head Insurance | D3: =COUNTIFS(Employee_Master!$F:$F,A3,Employee_Master!$C:$C,"Employee") -> 4 | E3: =COUNTIFS(Employee_Master!$F:$F,A3,Employee_Master!$C:$C,"Vacant Position") -> 1 | F3: Core Revenue | H3: Insurance sales targets.
A4: NBFC | B4: EMP-0302 | C4: Sachin Ghambir | D4: =COUNTIFS(Employee_Master!$F:$F,A4,Employee_Master!$C:$C,"Employee") -> 8 | E4: =COUNTIFS(Employee_Master!$F:$F,A4,Employee_Master!$C:$C,"Vacant Position") -> 0 | F4: Core Revenue | H4: Sales sub-team is Core Revenue; Credit, Collection and Ops sub-teams should be overridden to Revenue-Enabling at team level.
A5: jUMPP CS & Sales | B5: EMP-0254 | C5: Kapil Sachdev | D5: =COUNTIFS(Employee_Master!$F:$F,A5,Employee_Master!$C:$C,"Employee") -> 11 | E5: =COUNTIFS(Employee_Master!$F:$F,A5,Employee_Master!$C:$C,"Vacant Position") -> 0 | F5: Core Revenue | H5: Sales team = Core Revenue; CS team overridden to Customer Service.
A6: Product | B6: POS-0001 | C6: Managing Director | D6: =COUNTIFS(Employee_Master!$F:$F,A6,Employee_Master!$C:$C,"Employee") -> 71 | E6: =COUNTIFS(Employee_Master!$F:$F,A6,Employee_Master!$C:$C,"Vacant Position") -> 1 | F6: Revenue-Enabling | G6: Product | H6: Delivery on time is the primary measure.
A7: AI | B7: POS-0001 | C7: Managing Director | D7: =COUNTIFS(Employee_Master!$F:$F,A7,Employee_Master!$C:$C,"Employee") -> 11 | E7: =COUNTIFS(Employee_Master!$F:$F,A7,Employee_Master!$C:$C,"Vacant Position") -> 1 | F7: Revenue-Enabling
A8: Operations & BO | B8: EMP-0109 | C8: Pawan Kumar | D8: =COUNTIFS(Employee_Master!$F:$F,A8,Employee_Master!$C:$C,"Employee") -> 29 | E8: =COUNTIFS(Employee_Master!$F:$F,A8,Employee_Master!$C:$C,"Vacant Position") -> 0 | F8: Revenue-Enabling | G8: Operations; Back ofc & Operations
A9: Demat | B9: EMP-0109 | C9: Pawan Kumar | D9: =COUNTIFS(Employee_Master!$F:$F,A9,Employee_Master!$C:$C,"Employee") -> 8 | E9: =COUNTIFS(Employee_Master!$F:$F,A9,Employee_Master!$C:$C,"Vacant Position") -> 0 | F9: Revenue-Enabling
A10: RMS & Dealer | B10: EMP-0203 | C10: Ayushman Dey | D10: =COUNTIFS(Employee_Master!$F:$F,A10,Employee_Master!$C:$C,"Employee") -> 16 | E10: =COUNTIFS(Employee_Master!$F:$F,A10,Employee_Master!$C:$C,"Vacant Position") -> 0 | F10: Revenue-Enabling | H10: Dealer sub-team may be moved to Core Revenue if dealers carry brokerage targets.
A11: Compliance | B11: EMP-0109 | C11: Pawan Kumar | D11: =COUNTIFS(Employee_Master!$F:$F,A11,Employee_Master!$C:$C,"Employee") -> 6 | E11: =COUNTIFS(Employee_Master!$F:$F,A11,Employee_Master!$C:$C,"Vacant Position") -> 1 | F11: Revenue-Enabling | G11: Compliance | H11: Compliance is the core output, so the 20% compliance weight fits.
A12: Digital Marketing | B12: EMP-0117 | C12: Ramneek | D12: =COUNTIFS(Employee_Master!$F:$F,A12,Employee_Master!$C:$C,"Employee") -> 40 | E12: =COUNTIFS(Employee_Master!$F:$F,A12,Employee_Master!$C:$C,"Vacant Position") -> 0 | F12: Revenue-Enabling | H12: Acquisition/brand targets feed Achievement %.
A13: Client Support | B13: EMP-0219 | C13: Kapil Abrol | D13: =COUNTIFS(Employee_Master!$F:$F,A13,Employee_Master!$C:$C,"Employee") -> 35 | E13: =COUNTIFS(Employee_Master!$F:$F,A13,Employee_Master!$C:$C,"Vacant Position") -> 0 | F13: Customer Service (new) | G13: Customer Support | H13: CSAT is the primary measure; no original category weighted it correctly.
A14: IT | B14: EMP-0157 | C14: Patel Rajesh | D14: =COUNTIFS(Employee_Master!$F:$F,A14,Employee_Master!$C:$C,"Employee") -> 12 | E14: =COUNTIFS(Employee_Master!$F:$F,A14,Employee_Master!$C:$C,"Vacant Position") -> 0 | F14: Support | G14: IT / Tech
A15: HR | B15: EMP-0085 | C15: Balneet Birah | D15: =COUNTIFS(Employee_Master!$F:$F,A15,Employee_Master!$C:$C,"Employee") -> 12 | E15: =COUNTIFS(Employee_Master!$F:$F,A15,Employee_Master!$C:$C,"Vacant Position") -> 1 | F15: Support | G15: Human Resources; Learning & Development | H15: L&D is a sub-team under HR.
A16: Accounts | B16: EMP-0098 | C16: Aunj Ohri | D16: =COUNTIFS(Employee_Master!$F:$F,A16,Employee_Master!$C:$C,"Employee") -> 11 | E16: =COUNTIFS(Employee_Master!$F:$F,A16,Employee_Master!$C:$C,"Vacant Position") -> 0 | F16: Support | G16: Finance
A17: Admin | B17: EMP-0315 | C17: Dheeraj Dhiwan | D17: =COUNTIFS(Employee_Master!$F:$F,A17,Employee_Master!$C:$C,"Employee") -> 6 | E17: =COUNTIFS(Employee_Master!$F:$F,A17,Employee_Master!$C:$C,"Vacant Position") -> 0 | F17: Support
A18: Front Desk | B18: POS-0321 | C18: Department Head (not named in chart) | D18: =COUNTIFS(Employee_Master!$F:$F,A18,Employee_Master!$C:$C,"Employee") -> 2 | E18: =COUNTIFS(Employee_Master!$F:$F,A18,Employee_Master!$C:$C,"Vacant Position") -> 1 | F18: Support | H18: No head named in chart.
A19: Total | D19: =SUM(D2:D18) -> 319 | E19: =SUM(E2:E18) -> 6
A20: Note: Pawan Kumar (EMP-0109) heads Demat, Operations & BO and Compliance, and the Managing Director heads Product and AI, so the same head ID appears more than once. Headcount counts rows per department; a person who appears in two department charts is counted in both.

Sheet Category_Weights
A1: Metric | B1: Core Revenue | C1: Revenue-Enabling | D1: Support | E1: Customer Service (new) | F1: Change vs R&R_Parameters_2
A2: On-Time Rate | B2: 0.2 | C2: 0.3 | D2: 0.2 | E2: 0.2
A3: Achievement % | B3: 0.3 | C3: 0.25 | D3: 0 | E3: 0.15
A4: Compliance | B4: 0 | C4: 0.2 | D4: 0.1 | E4: 0.1
A5: CSAT | B5: 0.25 | C5: 0 | D5: 0 | E5: 0.3
A6: Quality | B6: 0.15 | C6: 0.15 | D6: 0.25 | E6: 0.25
A7: Productivity | B7: 0 | C7: 0 | D7: 0 | E7: 0 | F7: Defined but unweighted in all categories; used as an R&R tie-breaker and award input. Set a weight here to activate it.
A8: Collaboration | B8: 0.1 | C8: 0.1 | D8: 0.25 | E8: 0 | F8: "Culture" in Core Revenue is mapped to Collaboration (Culture was never defined).
A9: Innovation & Process Improvement | B9: 0 | C9: 0 | D9: 0.2 | E9: 0
A10: Total (must be 100%) | B10: =SUM(B2:B9) -> 1 | C10: =SUM(C2:C9) -> 1 | D10: =SUM(D2:D9) -> 1 | E10: =SUM(E2:E9) -> 1
A11: Check | B11: =IF(ROUND(B10,4)=1,"OK","FIX") -> OK | C11: =IF(ROUND(C10,4)=1,"OK","FIX") -> OK | D11: =IF(ROUND(D10,4)=1,"OK","FIX") -> OK | E11: =IF(ROUND(E10,4)=1,"OK","FIX") -> OK
A13: The 60% Quantifiable / 40% Qualitative split in R_R_Parameters_2 is retired: its listed sub-weights summed to 75-100% and 50-65%. Category weights above are the single source of truth. Customer Service is a proposed new category and needs management approval.

Sheet Tracker_Cleaned
A1: Src Row | B1: Project ID | C1: Project | D1: Task ID | E1: Task / Deliverable | F1: Assignee (as typed) | G1: Emp ID | H1: Assignee (resolved) | I1: Match Note | J1: Assignment Role | K1: Contribution % | L1: Department | M1: Project Owner | N1: Priority | O1: Start Date | P1: Target Date | Q1: Completed Date | R1: Original Status | S1: Mapped Status | T1: Timing (auto) | U1: Blocker Type | V1: Delay Reason | W1: Validated? | X1: Excludable if Late? | Y1: On-Time Eligible (auto) | Z1: Data Quality Flags
A2: 4 | B2: PRJ-001 | C2: Loan Changes (Advance Salary) | D2: PRJ-001-T01 | E2: Loan Changes (Advance Salary) | F2: Sachin | G2: EMP-0082 | H2: Sachin Barnwal | I2: Context: UI/UX under Pradeep Thakur | J2: Owner | K2: 1 | L2: Product | M2: Pradeep Thakur | N2: High | O2: 46258 | P2: 46258 | Q2: 46258 | R2: Completed | S2: Completed | T2: =IF(P2="","No deadline",IF(Q2<>"",IF(Q2>P2,"Late","On time"),IF(README!$B$4>P2,"Overdue","Open"))) -> On time | Y2: =IF(AND(S2="Completed",P2<>"",Q2<>""),IF(AND(T2="Late",X2="Yes",W2="Yes"),"Excluded (validated delay)","Yes"),"No") -> Yes
A3: 5 | B3: PRJ-002 | C3: Trade.Shoonya Global Dashboard (Corporate actions) | D3: PRJ-002-T01 | E3: Trade.Shoonya Global Dashboard (Corporate actions) | F3: Sachin | G3: EMP-0082 | H3: Sachin Barnwal | I3: Context: UI/UX under Pradeep Thakur | J3: Owner | K3: 1 | L3: Product | M3: Pradeep Thakur | N3: High | O3: 46238 | P3: 46254 | Q3: 46254 | R3: Completed | S3: Completed | T3: =IF(P3="","No deadline",IF(Q3<>"",IF(Q3>P3,"Late","On time"),IF(README!$B$4>P3,"Overdue","Open"))) -> On time | Y3: =IF(AND(S3="Completed",P3<>"",Q3<>""),IF(AND(T3="Late",X3="Yes",W3="Yes"),"Excluded (validated delay)","Yes"),"No") -> Yes
A4: 6 | B4: PRJ-003 | C4: Mobile-Trade.Shoonya Global Dashboard (Corporate actions) | D4: PRJ-003-T01 | E4: Mobile-Trade.Shoonya Global Dashboard (Corporate actions) | F4: Sachin | G4: EMP-0082 | H4: Sachin Barnwal | I4: Context: UI/UX under Pradeep Thakur | J4: Owner | K4: 1 | L4: Product | M4: Pradeep Thakur | N4: High | O4: 46253 | P4: 46255 | Q4: 46255 | R4: Completed | S4: Completed | T4: =IF(P4="","No deadline",IF(Q4<>"",IF(Q4>P4,"Late","On time"),IF(README!$B$4>P4,"Overdue","Open"))) -> On time | Y4: =IF(AND(S4="Completed",P4<>"",Q4<>""),IF(AND(T4="Late",X4="Yes",W4="Yes"),"Excluded (validated delay)","Yes"),"No") -> Yes
A5: 7 | B5: PRJ-004 | C5: Shoonya R&R | D5: PRJ-004-T01 | E5: Shoonya R&R | F5: Sachin | G5: EMP-0082 | H5: Sachin Barnwal | I5: Context: UI/UX under Pradeep Thakur | J5: Owner | K5: 1 | L5: Product | M5: Pradeep Thakur | N5: High | O5: 46241 | P5: 46262 | Q5: 46242 | R5: On Hold | S5: On Hold | T5: =IF(P5="","No deadline",IF(Q5<>"",IF(Q5>P5,"Late","On time"),IF(README!$B$4>P5,"Overdue","Open"))) -> On time | U5: Management reprioritisation | V5: Working on MF | W5: Yes | X5: Yes | Y5: =IF(AND(S5="Completed",P5<>"",Q5<>""),IF(AND(T5="Late",X5="Yes",W5="Yes"),"Excluded (validated delay)","Yes"),"No") -> No | Z5: Has completed date but status is On Hold; Completed date kept for reference; not counted as completed
A6: 8 | B6: PRJ-005 | C6: Trade Shoonya: Dark theme | D6: PRJ-005-T01 | E6: Trade Shoonya: Dark theme | F6: Sachin | G6: EMP-0082 | H6: Sachin Barnwal | I6: Context: UI/UX under Pradeep Thakur | J6: Owner | K6: 1 | L6: Product | M6: Pradeep Thakur | N6: Medium | O6: 46275 | P6: 46283 | R6: On Hold | S6: On Hold | T6: =IF(P6="","No deadline",IF(Q6<>"",IF(Q6>P6,"Late","On time"),IF(README!$B$4>P6,"Overdue","Open"))) -> Overdue | U6: Management reprioritisation | V6: Working on R&R and MF | W6: Yes | X6: Yes | Y6: =IF(AND(S6="Completed",P6<>"",Q6<>""),IF(AND(T6="Late",X6="Yes",W6="Yes"),"Excluded (validated delay)","Yes"),"No") -> No
A7: 9 | B7: PRJ-006 | C7: Jumpp R&R | D7: PRJ-006-T01 | E7: Jumpp R&R | F7: Harsh | G7: EMP-0084 | H7: Harsh | I7: Context: UI/UX under Pradeep Thakur | J7: Owner | K7: 1 | L7: Product | M7: Pradeep Thakur | N7: High | O7: 46244 | P7: 46248 | R7: In Review | S7: In Review | T7: =IF(P7="","No deadline",IF(Q7<>"",IF(Q7>P7,"Late","On time"),IF(README!$B$4>P7,"Overdue","Open"))) -> Overdue | U7: Rework (own team feedback) | V7: Inernal feedback incorporated | W7: Yes | X7: No | Y7: =IF(AND(S7="Completed",P7<>"",Q7<>""),IF(AND(T7="Late",X7="Yes",W7="Yes"),"Excluded (validated delay)","Yes"),"No") -> No
A8: 10 | B8: PRJ-007 | C8: Rewards Journey UI (Milestones or Campaign) | D8: PRJ-007-T01 | E8: Rewards Journey UI (Milestones or Campaign) | F8: Harsh | G8: EMP-0084 | H8: Harsh | I8: Context: UI/UX under Pradeep Thakur | J8: Owner | K8: 1 | L8: Product | M8: Pradeep Thakur | N8: High | O8: 46254 | P8: 46258 | Q8: 46260 | R8: In Review | S8: In Review | T8: =IF(P8="","No deadline",IF(Q8<>"",IF(Q8>P8,"Late","On time"),IF(README!$B$4>P8,"Overdue","Open"))) -> Late | Y8: =IF(AND(S8="Completed",P8<>"",Q8<>""),IF(AND(T8="Late",X8="Yes",W8="Yes"),"Excluded (validated delay)","Yes"),"No") -> No | Z8: Has completed date but status is In Review; Completed date kept for reference; not counted as completed
A9: 11 | B9: PRJ-008 | C9: Digital Silver | D9: PRJ-008-T01 | E9: Digital Silver | F9: Maninder | G9: EMP-0083 | H9: Maninder Singh | I9: Context: Sr. UI/UX (not the SEO Maninder Singh) | J9: Owner | K9: 1 | L9: Product | M9: Pradeep Thakur | N9: High | O9: 46249 | P9: 46258 | R9: In Review | S9: In Review | T9: =IF(P9="","No deadline",IF(Q9<>"",IF(Q9>P9,"Late","On time"),IF(README!$B$4>P9,"Overdue","Open"))) -> Overdue | Y9: =IF(AND(S9="Completed",P9<>"",Q9<>""),IF(AND(T9="Late",X9="Yes",W9="Yes"),"Excluded (validated delay)","Yes"),"No") -> No
A10: 12 | B10: PRJ-009 | C10: Digital Silver SIP | D10: PRJ-009-T01 | E10: Digital Silver SIP | F10: Maninder | G10: EMP-0083 | H10: Maninder Singh | I10: Context: Sr. UI/UX (not the SEO Maninder Singh) | J10: Owner | K10: 1 | L10: Product | M10: Pradeep Thakur | N10: High | O10: 46250 | P10: 46259 | R10: In Review | S10: In Review | T10: =IF(P10="","No deadline",IF(Q10<>"",IF(Q10>P10,"Late","On time"),IF(README!$B$4>P10,"Overdue","Open"))) -> Overdue | Y10: =IF(AND(S10="Completed",P10<>"",Q10<>""),IF(AND(T10="Late",X10="Yes",W10="Yes"),"Excluded (validated delay)","Yes"),"No") -> No
A11: 13 | B11: PRJ-010 | C11: Digital Gold SIP | D11: PRJ-010-T01 | E11: Digital Gold SIP | F11: Maninder | G11: EMP-0083 | H11: Maninder Singh | I11: Context: Sr. UI/UX (not the SEO Maninder Singh) | J11: Owner | K11: 1 | L11: Product | M11: Pradeep Thakur | N11: High | O11: 46251 | P11: 46260 | R11: In Review | S11: In Review | T11: =IF(P11="","No deadline",IF(Q11<>"",IF(Q11>P11,"Late","On time"),IF(README!$B$4>P11,"Overdue","Open"))) -> Overdue | Y11: =IF(AND(S11="Completed",P11<>"",Q11<>""),IF(AND(T11="Late",X11="Yes",W11="Yes"),"Excluded (validated delay)","Yes"),"No") -> No
A12: 14 | B12: PRJ-011 | C12: Physical Silver | D12: PRJ-011-T01 | E12: Physical Silver | F12: Maninder | G12: EMP-0083 | H12: Maninder Singh | I12: Context: Sr. UI/UX (not the SEO Maninder Singh) | J12: Owner | K12: 1 | L12: Product | M12: Pradeep Thakur | N12: High | O12: 46252 | P12: 46261 | R12: In Review | S12: In Review | T12: =IF(P12="","No deadline",IF(Q12<>"",IF(Q12>P12,"Late","On time"),IF(README!$B$4>P12,"Overdue","Open"))) -> Overdue | Y12: =IF(AND(S12="Completed",P12<>"",Q12<>""),IF(AND(T12="Late",X12="Yes",W12="Yes"),"Excluded (validated delay)","Yes"),"No") -> No
A13: 15 | B13: PRJ-012 | C13: Physical Gold | D13: PRJ-012-T01 | E13: Physical Gold | F13: Maninder | G13: EMP-0083 | H13: Maninder Singh | I13: Context: Sr. UI/UX (not the SEO Maninder Singh) | J13: Owner | K13: 1 | L13: Product | M13: Pradeep Thakur | N13: High | O13: 46253 | P13: 46262 | R13: In Review | S13: In Review | T13: =IF(P13="","No deadline",IF(Q13<>"",IF(Q13>P13,"Late","On time"),IF(README!$B$4>P13,"Overdue","Open"))) -> Overdue | Y13: =IF(AND(S13="Completed",P13<>"",Q13<>""),IF(AND(T13="Late",X13="Yes",W13="Yes"),"Excluded (validated delay)","Yes"),"No") -> No
A14: 16 | B14: PRJ-013 | C14: Jumpp Website 1.1 | D14: PRJ-013-T01 | E14: Jumpp Website 1.1 | F14: Maninder | G14: EMP-0083 | H14: Maninder Singh | I14: Context: Sr. UI/UX (not the SEO Maninder Singh) | J14: Owner | K14: 1 | L14: Product | M14: Pradeep Thakur | N14: High | O14: 46174 | P14: 46265 | Q14: 46255 | R14: On Hold | S14: On Hold | T14: =IF(P14="","No deadline",IF(Q14<>"",IF(Q14>P14,"Late","On time"),IF(README!$B$4>P14,"Overdue","Open"))) -> On time | U14: Internal dependency (other team review) | V14: DM team feedbacks | W14: Yes | X14: Yes | Y14: =IF(AND(S14="Completed",P14<>"",Q14<>""),IF(AND(T14="Late",X14="Yes",W14="Yes"),"Excluded (validated delay)","Yes"),"No") -> No | Z14: Has completed date but status is On Hold; Completed date kept for reference; not counted as completed
A15: 17 | B15: PRJ-014 | C15: Insurance Chatbot | D15: PRJ-014-T01 | E15: Insurance Chatbot | F15: Maninder | G15: EMP-0083 | H15: Maninder Singh | I15: Context: Sr. UI/UX (not the SEO Maninder Singh) | J15: Owner | K15: 1 | L15: Product | M15: Pradeep Thakur | N15: High | O15: 46261 | P15: 46272 | R15: Ongoing | S15: In Progress | T15: =IF(P15="","No deadline",IF(Q15<>"",IF(Q15>P15,"Late","On time"),IF(README!$B$4>P15,"Overdue","Open"))) -> Overdue | Y15: =IF(AND(S15="Completed",P15<>"",Q15<>""),IF(AND(T15="Late",X15="Yes",W15="Yes"),"Excluded (validated delay)","Yes"),"No") -> No
A16: 18 | B16: PRJ-015 | C16: Shoonya Website Enhancements | D16: PRJ-015-T01 | E16: Shoonya Website Enhancements | F16: Maninder | G16: EMP-0083 | H16: Maninder Singh | I16: Context: Sr. UI/UX (not the SEO Maninder Singh) | J16: Owner | K16: 1 | L16: Product | M16: Pradeep Thakur | N16: High | O16: 46261 | P16: 46261 | R16: On Hold | S16: On Hold | T16: =IF(P16="","No deadline",IF(Q16<>"",IF(Q16>P16,"Late","On time"),IF(README!$B$4>P16,"Overdue","Open"))) -> Overdue | U16: Management reprioritisation | V16: Due to jUMPP task | W16: Yes | X16: Yes | Y16: =IF(AND(S16="Completed",P16<>"",Q16<>""),IF(AND(T16="Late",X16="Yes",W16="Yes"),"Excluded (validated delay)","Yes"),"No") -> No
A17: 19 | B17: PRJ-016 | C17: Onboarding Pan Skip Transition History UI (Need to be updated) | D17: PRJ-016-T01 | E17: Onboarding Pan Skip Transition History UI (Need to be updated) | F17: Harsh | G17: EMP-0084 | H17: Harsh | I17: Context: UI/UX under Pradeep Thakur | J17: Owner | K17: 1 | L17: Product | M17: Pradeep Thakur | N17: High | O17: 46259 | P17: 46259 | Q17: 46259 | R17: Completed | S17: Completed | T17: =IF(P17="","No deadline",IF(Q17<>"",IF(Q17>P17,"Late","On time"),IF(README!$B$4>P17,"Overdue","Open"))) -> On time | Y17: =IF(AND(S17="Completed",P17<>"",Q17<>""),IF(AND(T17="Late",X17="Yes",W17="Yes"),"Excluded (validated delay)","Yes"),"No") -> Yes
A18: 20 | B18: PRJ-017 | C18: SensAI | D18: PRJ-017-T01 | E18: SensAI | F18: Sachin | G18: EMP-0082 | H18: Sachin Barnwal | I18: Context: UI/UX under Pradeep Thakur | J18: Owner | K18: 1 | L18: Product | M18: Pradeep Thakur | N18: High | O18: 46245 | P18: 46248 | Q18: 46266 | R18: On Hold | S18: On Hold | T18: =IF(P18="","No deadline",IF(Q18<>"",IF(Q18>P18,"Late","On time"),IF(README!$B$4>P18,"Overdue","Open"))) -> Late | U18: Management reprioritisation | V18: Working on R&R and MF | W18: Yes | X18: Yes | Y18: =IF(AND(S18="Completed",P18<>"",Q18<>""),IF(AND(T18="Late",X18="Yes",W18="Yes"),"Excluded (validated delay)","Yes"),"No") -> No | Z18: Has completed date but status is On Hold; Completed date kept for reference; not counted as completed
A19: 21 | B19: PRJ-018 | C19: Shoonya Bonds- Entry points and graphics UI | D19: PRJ-018-T01 | E19: Shoonya Bonds- Entry points and graphics UI | F19: Sachin | G19: EMP-0082 | H19: Sachin Barnwal | I19: Context: UI/UX under Pradeep Thakur | J19: Owner | K19: 1 | L19: Product | M19: Pradeep Thakur | N19: High | O19: 46237 | P19: 46237 | R19: Completed | S19: In Review | T19: =IF(P19="","No deadline",IF(Q19<>"",IF(Q19>P19,"Late","On time"),IF(README!$B$4>P19,"Overdue","Open"))) -> Overdue | Y19: =IF(AND(S19="Completed",P19<>"",Q19<>""),IF(AND(T19="Late",X19="Yes",W19="Yes"),"Excluded (validated delay)","Yes"),"No") -> No | Z19: Completed without completed date; Moved to In Review until completion date is recorded
A20: 22 | B20: PRJ-019 | C20: Shoonya MF | D20: PRJ-019-T01 | E20: Shoonya MF | F20: Sachin | G20: EMP-0082 | H20: Sachin Barnwal | I20: Context: UI/UX under Pradeep Thakur | J20: Owner | K20: 1 | L20: Product | M20: Pradeep Thakur | N20: High | O20: 46205 | P20: 46234 | Q20: 46266 | R20: In Review | S20: In Review | T20: =IF(P20="","No deadline",IF(Q20<>"",IF(Q20>P20,"Late","On time"),IF(README!$B$4>P20,"Overdue","Open"))) -> Late | U20: Requirement change | V20: Recived update requirement based on MF: API | W20: Yes | X20: Yes | Y20: =IF(AND(S20="Completed",P20<>"",Q20<>""),IF(AND(T20="Late",X20="Yes",W20="Yes"),"Excluded (validated delay)","Yes"),"No") -> No | Z20: Has completed date but status is In Review; Completed date kept for reference; not counted as completed
A21: 23 | B21: PRJ-020 | C21: Algo Trading mobile app | D21: PRJ-020-T01 | E21: Algo Trading mobile app | F21: Sachin | G21: EMP-0082 | H21: Sachin Barnwal | I21: Context: UI/UX under Pradeep Thakur | J21: Owner | K21: 1 | L21: Product | M21: Pradeep Thakur | N21: High | O21: 46244 | P21: 46248 | R21: In Review | S21: In Review | T21: =IF(P21="","No deadline",IF(Q21<>"",IF(Q21>P21,"Late","On time"),IF(README!$B$4>P21,"Overdue","Open"))) -> Overdue | Y21: =IF(AND(S21="Completed",P21<>"",Q21<>""),IF(AND(T21="Late",X21="Yes",W21="Yes"),"Excluded (validated delay)","Yes"),"No") -> No
A22: 24 | B22: PRJ-021 | C22: App Tour | D22: PRJ-021-T01 | E22: App Tour | F22: Harsh | G22: EMP-0084 | H22: Harsh | I22: Context: UI/UX under Pradeep Thakur | J22: Owner | K22: 1 | L22: Product | M22: Pradeep Thakur | N22: High | O22: 46197 | P22: 46197 | R22: In Review | S22: In Review | T22: =IF(P22="","No deadline",IF(Q22<>"",IF(Q22>P22,"Late","On time"),IF(README!$B$4>P22,"Overdue","Open"))) -> Overdue | Y22: =IF(AND(S22="Completed",P22<>"",Q22<>""),IF(AND(T22="Late",X22="Yes",W22="Yes"),"Excluded (validated delay)","Yes"),"No") -> No
A23: 25 | B23: PRJ-022 | C23: Widgets | D23: PRJ-022-T01 | E23: Widgets | F23: Harsh | G23: EMP-0084 | H23: Harsh | I23: Context: UI/UX under Pradeep Thakur | J23: Owner | K23: 1 | L23: Product | M23: Pradeep Thakur | N23: High | O23: 46197 | P23: 46197 | R23: In Review | S23: In Review | T23: =IF(P23="","No deadline",IF(Q23<>"",IF(Q23>P23,"Late","On time"),IF(README!$B$4>P23,"Overdue","Open"))) -> Overdue | Y23: =IF(AND(S23="Completed",P23<>"",Q23<>""),IF(AND(T23="Late",X23="Yes",W23="Yes"),"Excluded (validated delay)","Yes"),"No") -> No
A24: 26 | B24: PRJ-023 | C24: MTF Interest Charges updated | D24: PRJ-023-T01 | E24: MTF Interest Rate changes in KORP | F24: Vinay | G24: EMP-0170 | H24: Vinay Thakur | I24: Context: Ops Executive | J24: Owner | K24: 1 | L24: Operations & BO | M24: Pawan | N24: High | O24: 46235 | P24: 46266 | R24: Delayed | S24: Blocked | T24: =IF(P24="","No deadline",IF(Q24<>"",IF(Q24>P24,"Late","On time"),IF(README!$B$4>P24,"Overdue","Open"))) -> Overdue | U24: Internal dependency (Product/Development) | V24: Product team Delay | X24: Yes | Y24: =IF(AND(S24="Completed",P24<>"",Q24<>""),IF(AND(T24="Late",X24="Yes",W24="Yes"),"Excluded (validated delay)","Yes"),"No") -> No | Z24: "Delayed" is now derived from dates, not a status
A25: 27 | B25: PRJ-024 | C25: Bond | D25: PRJ-024-T01 | E25: Bond Back office intigration with Exchnages | F25: Pawan | G25: EMP-0109 | H25: Pawan Kumar | I25: Context: AVP-Operations (not the Software Engineer) | J25: Owner | K25: 1 | L25: Operations & BO | M25: Pawan | N25: High | O25: 46252 | R25: Ongoing | S25: In Progress | T25: =IF(P25="","No deadline",IF(Q25<>"",IF(Q25>P25,"Late","On time"),IF(README!$B$4>P25,"Overdue","Open"))) -> No deadline | U25: Internal dependency (Product/Development) | V25: Product team working | X25: Yes | Y25: =IF(AND(S25="Completed",P25<>"",Q25<>""),IF(AND(T25="Late",X25="Yes",W25="Yes"),"Excluded (validated delay)","Yes"),"No") -> No | Z25: Target date missing
A26: 28 | B26: PRJ-025 | C26: Refer and Reward | D26: PRJ-025-T01 | E26: for new client refer reward in KORP | F26: pawan | G26: EMP-0109 | H26: Pawan Kumar | I26: Context: AVP-Operations (not the Software Engineer) | J26: Owner | K26: 1 | L26: Operations & BO | M26: Pawan | N26: Medium | O26: 46244 | R26: Ongoing | S26: In Progress | T26: =IF(P26="","No deadline",IF(Q26<>"",IF(Q26>P26,"Late","On time"),IF(README!$B$4>P26,"Overdue","Open"))) -> No deadline | U26: Internal dependency (Product/Development) | V26: Product team working | X26: Yes | Y26: =IF(AND(S26="Completed",P26<>"",Q26<>""),IF(AND(T26="Late",X26="Yes",W26="Yes"),"Excluded (validated delay)","Yes"),"No") -> No | Z26: Target date missing
A27: 29 | B27: PRJ-026 | C27: Account opening journey with (AI) incorporation | D27: PRJ-026-T01 | E27: New account opening journey with (AI) incorporation | F27: Vivek | G27: EMP-0174 | H27: Vivek Sharma | I27: Exact first-name match in Ops & BO | J27: Owner | K27: 1 | L27: Operations & BO | M27: Pawan | N27: High | O27: 46126 | Q27: 46308 | R27: Delayed | S27: Blocked | T27: =IF(P27="","No deadline",IF(Q27<>"",IF(Q27>P27,"Late","On time"),IF(README!$B$4>P27,"Overdue","Open"))) -> No deadline | U27: Internal dependency (Product/Development) | V27: launch of p2 delayed this project | X27: Yes | Y27: =IF(AND(S27="Completed",P27<>"",Q27<>""),IF(AND(T27="Late",X27="Yes",W27="Yes"),"Excluded (validated delay)","Yes"),"No") -> No | Z27: Target date missing; Completed date is in the future; Has completed date but status is Delayed; "Delayed" is now derived from dates, not a status
A28: 30 | B28: PRJ-026 | C28: Account opening journey with (AI) incorporation | D28: PRJ-026-T01 | E28: New account opening journey with (AI) incorporation | F28: Jaidev | G28: EMP-0181 | H28: Jai Dev Singh | I28: Spelling differs (Jaidev vs Jai Dev) | J28: Owner | K28: 1 | L28: Operations & BO | M28: Vivek | N28: High | O28: 46126 | Q28: 46308 | R28: Delayed | S28: Blocked | T28: =IF(P28="","No deadline",IF(Q28<>"",IF(Q28>P28,"Late","On time"),IF(README!$B$4>P28,"Overdue","Open"))) -> No deadline | U28: Internal dependency (Product/Development) | V28: launch of p2 delayed this project | X28: Yes | Y28: =IF(AND(S28="Completed",P28<>"",Q28<>""),IF(AND(T28="Late",X28="Yes",W28="Yes"),"Excluded (validated delay)","Yes"),"No") -> No | Z28: Target date missing; Completed date is in the future; Has completed date but status is Delayed; "Delayed" is now derived from dates, not a status
A29: 31 | B29: PRJ-027 | C29: (AI) integrated Module for Prism Dashboard (BO) | D29: PRJ-027-T01 | E29: BO Daily MIS | F29: Vivek | G29: EMP-0174 | H29: Vivek Sharma | I29: Exact first-name match in Ops & BO | J29: Owner | K29: 1 | L29: Operations & BO | M29: Pawan | N29: Medium | O29: 46237 | P29: 46265 | R29: Ongoing | S29: In Progress | T29: =IF(P29="","No deadline",IF(Q29<>"",IF(Q29>P29,"Late","On time"),IF(README!$B$4>P29,"Overdue","Open"))) -> Overdue | Y29: =IF(AND(S29="Completed",P29<>"",Q29<>""),IF(AND(T29="Late",X29="Yes",W29="Yes"),"Excluded (validated delay)","Yes"),"No") -> No
A30: 32 | B30: PRJ-027 | C30: (AI) integrated Module for Prism Dashboard (BO) | D30: PRJ-027-T01 | E30: BO Daily MIS | F30: Jaidev | G30: EMP-0181 | H30: Jai Dev Singh | I30: Spelling differs (Jaidev vs Jai Dev) | J30: Owner | K30: 1 | L30: Operations & BO | M30: Vivek | N30: Medium | O30: 46237 | P30: 46265 | R30: Ongoing | S30: In Progress | T30: =IF(P30="","No deadline",IF(Q30<>"",IF(Q30>P30,"Late","On time"),IF(README!$B$4>P30,"Overdue","Open"))) -> Overdue | Y30: =IF(AND(S30="Completed",P30<>"",Q30<>""),IF(AND(T30="Late",X30="Yes",W30="Yes"),"Excluded (validated delay)","Yes"),"No") -> No
A31: 33 | B31: PRJ-027 | C31: (AI) integrated Module for Prism Dashboard (BO) | D31: PRJ-027-T01 | E31: BO Daily MIS | F31: Kanav | G31: EMP-0175 | H31: Kanav Verma | I31: Exact first-name match | J31: Owner | K31: 1 | L31: Operations & BO | M31: Vivek | N31: Medium | O31: 46237 | P31: 46265 | R31: Ongoing | S31: In Progress | T31: =IF(P31="","No deadline",IF(Q31<>"",IF(Q31>P31,"Late","On time"),IF(README!$B$4>P31,"Overdue","Open"))) -> Overdue | Y31: =IF(AND(S31="Completed",P31<>"",Q31<>""),IF(AND(T31="Late",X31="Yes",W31="Yes"),"Excluded (validated delay)","Yes"),"No") -> No
A32: 34 | B32: PRJ-027 | C32: (AI) integrated Module for Prism Dashboard (BO) | D32: PRJ-027-T01 | E32: BO Daily MIS | F32: Akash | G32: EMP-0187 | H32: Akashdeep | I32: Probable: Akashdeep (BO Team Lead) - confirm | J32: Owner | K32: 1 | L32: Operations & BO | M32: Vivek | N32: Medium | O32: 46237 | P32: 46265 | R32: Ongoing | S32: In Progress | T32: =IF(P32="","No deadline",IF(Q32<>"",IF(Q32>P32,"Late","On time"),IF(README!$B$4>P32,"Overdue","Open"))) -> Overdue | Y32: =IF(AND(S32="Completed",P32<>"",Q32<>""),IF(AND(T32="Late",X32="Yes",W32="Yes"),"Excluded (validated delay)","Yes"),"No") -> No
A33: 35 | B33: PRJ-028 | C33: Quick Pledge/Unpledge | D33: PRJ-028-T01 | E33: Auto process for Pledge/Unpledge | F33: Yogesh | G33: EMP-0110 | H33: Yogesh | I33: Exact match | J33: Owner | K33: 1 | L33: Operations & BO | M33: Pawan | N33: High | O33: 46203 | P33: 46276 | R33: Ongoing | S33: In Progress | T33: =IF(P33="","No deadline",IF(Q33<>"",IF(Q33>P33,"Late","On time"),IF(README!$B$4>P33,"Overdue","Open"))) -> Overdue | U33: Internal dependency (Product/Development) | V33: Product team working | X33: Yes | Y33: =IF(AND(S33="Completed",P33<>"",Q33<>""),IF(AND(T33="Late",X33="Yes",W33="Yes"),"Excluded (validated delay)","Yes"),"No") -> No
A34: 36 | B34: PRJ-028 | C34: Quick Pledge/Unpledge | D34: PRJ-028-T01 | E34: Auto process for Pledge/Unpledge | F34: Atul | G34: EMP-0112 | H34: Atul Kumar | I34: Context: reports to Yogesh (Demat) | J34: Owner | K34: 1 | L34: Operations & BO | M34: Yogesh | N34: High | O34: 46203 | P34: 46276 | R34: Ongoing | S34: In Progress | T34: =IF(P34="","No deadline",IF(Q34<>"",IF(Q34>P34,"Late","On time"),IF(README!$B$4>P34,"Overdue","Open"))) -> Overdue | U34: Internal dependency (Product/Development) | V34: Product team working | X34: Yes | Y34: =IF(AND(S34="Completed",P34<>"",Q34<>""),IF(AND(T34="Late",X34="Yes",W34="Yes"),"Excluded (validated delay)","Yes"),"No") -> No
A35: 37 | B35: PRJ-029 | C35: Buyback Feature Implementation | D35: PRJ-029-T01 | E35: Auto process for Buyback | F35: Yogesh | G35: EMP-0110 | H35: Yogesh | I35: Exact match | J35: Owner | K35: 1 | L35: Operations & BO | M35: Pawan | N35: Medium | O35: 46235 | R35: Ongoing | S35: In Progress | T35: =IF(P35="","No deadline",IF(Q35<>"",IF(Q35>P35,"Late","On time"),IF(README!$B$4>P35,"Overdue","Open"))) -> No deadline | U35: Internal dependency (Product/Development) | V35: Product team working | X35: Yes | Y35: =IF(AND(S35="Completed",P35<>"",Q35<>""),IF(AND(T35="Late",X35="Yes",W35="Yes"),"Excluded (validated delay)","Yes"),"No") -> No | Z35: Target date missing
A36: 38 | B36: PRJ-029 | C36: Buyback Feature Implementation | D36: PRJ-029-T01 | E36: Auto process for Buyback | F36: Atul | G36: EMP-0112 | H36: Atul Kumar | I36: Context: reports to Yogesh (Demat) | J36: Owner | K36: 1 | L36: Operations & BO | M36: Yogesh | N36: Medium | O36: 46235 | R36: Ongoing | S36: In Progress | T36: =IF(P36="","No deadline",IF(Q36<>"",IF(Q36>P36,"Late","On time"),IF(README!$B$4>P36,"Overdue","Open"))) -> No deadline | U36: Internal dependency (Product/Development) | V36: Product team working | X36: Yes | Y36: =IF(AND(S36="Completed",P36<>"",Q36<>""),IF(AND(T36="Late",X36="Yes",W36="Yes"),"Excluded (validated delay)","Yes"),"No") -> No | Z36: Target date missing
A37: 39 | B37: PRJ-030 | C37: SenS-AI 1.1 Enhancement | D37: PRJ-030-T01 | E37: Development of Module in Mobile app | F37: Saksham | G37: EMP-0048 | H37: Saksham | I37: Exact match | J37: Contributor | K37: 0.2 | L37: Product | N37: High | P37: 46268 | R37: Delayed | S37: Blocked | T37: =IF(P37="","No deadline",IF(Q37<>"",IF(Q37>P37,"Late","On time"),IF(README!$B$4>P37,"Overdue","Open"))) -> Overdue | U37: Management reprioritisation | V37: due to an urgent requirement, we are releasing changes to MTF 3x the app is in review and once that app is released, we will publish SensAI | X37: Yes | Y37: =IF(AND(S37="Completed",P37<>"",Q37<>""),IF(AND(T37="Late",X37="Yes",W37="Yes"),"Excluded (validated delay)","Yes"),"No") -> No | Z37: Project owner missing; "Delayed" is now derived from dates, not a status; Multiple assignees in one cell - split; confirm owner and contribution %
A38: 39 | B38: PRJ-030 | C38: SenS-AI 1.1 Enhancement | D38: PRJ-030-T01 | E38: Development of Module in Mobile app | F38: Jaspreet | G38: EMP-0058 | H38: Jaspreet Singh | I38: Exact first-name match | J38: Contributor | K38: 0.2 | L38: Product | N38: High | P38: 46268 | R38: Delayed | S38: Blocked | T38: =IF(P38="","No deadline",IF(Q38<>"",IF(Q38>P38,"Late","On time"),IF(README!$B$4>P38,"Overdue","Open"))) -> Overdue | U38: Management reprioritisation | V38: due to an urgent requirement, we are releasing changes to MTF 3x the app is in review and once that app is released, we will publish SensAI | X38: Yes | Y38: =IF(AND(S38="Completed",P38<>"",Q38<>""),IF(AND(T38="Late",X38="Yes",W38="Yes"),"Excluded (validated delay)","Yes"),"No") -> No | Z38: Project owner missing; "Delayed" is now derived from dates, not a status; Multiple assignees in one cell - split; confirm owner and contribution %
A39: 39 | B39: PRJ-030 | C39: SenS-AI 1.1 Enhancement | D39: PRJ-030-T01 | E39: Development of Module in Mobile app | F39: Jatin | G39: EMP-0046 | H39: Jatin Vashisht | I39: Exact first-name match | J39: Contributor | K39: 0.2 | L39: Product | N39: High | P39: 46268 | R39: Delayed | S39: Blocked | T39: =IF(P39="","No deadline",IF(Q39<>"",IF(Q39>P39,"Late","On time"),IF(README!$B$4>P39,"Overdue","Open"))) -> Overdue | U39: Management reprioritisation | V39: due to an urgent requirement, we are releasing changes to MTF 3x the app is in review and once that app is released, we will publish SensAI | X39: Yes | Y39: =IF(AND(S39="Completed",P39<>"",Q39<>""),IF(AND(T39="Late",X39="Yes",W39="Yes"),"Excluded (validated delay)","Yes"),"No") -> No | Z39: Project owner missing; "Delayed" is now derived from dates, not a status; Multiple assignees in one cell - split; confirm owner and contribution %
A40: 39 | B40: PRJ-030 | C40: SenS-AI 1.1 Enhancement | D40: PRJ-030-T01 | E40: Development of Module in Mobile app | F40: Aryan | G40: EMP-0027 | H40: Aryan Raj | I40: Exact first-name match | J40: Contributor | K40: 0.2 | L40: Product | N40: High | P40: 46268 | R40: Delayed | S40: Blocked | T40: =IF(P40="","No deadline",IF(Q40<>"",IF(Q40>P40,"Late","On time"),IF(README!$B$4>P40,"Overdue","Open"))) -> Overdue | U40: Management reprioritisation | V40: due to an urgent requirement, we are releasing changes to MTF 3x the app is in review and once that app is released, we will publish SensAI | X40: Yes | Y40: =IF(AND(S40="Completed",P40<>"",Q40<>""),IF(AND(T40="Late",X40="Yes",W40="Yes"),"Excluded (validated delay)","Yes"),"No") -> No | Z40: Project owner missing; "Delayed" is now derived from dates, not a status; Multiple assignees in one cell - split; confirm owner and contribution %
...

Sheet Project_Register
A1: Project ID | B1: Project | C1: Department | D1: Owner | E1: Priority | F1: Assignment Rows | G1: Completed | H1: Blocked | I1: Late/Overdue | J1: Missing Deadline | K1: Flags
A2: PRJ-001 | B2: Loan Changes (Advance Salary) | C2: Product | D2: Pradeep Thakur | E2: High | F2: =COUNTIF(Tracker_Cleaned!$B$2:$B$176,A2) -> 1 | G2: =COUNTIFS(Tracker_Cleaned!$B$2:$B$176,A2,Tracker_Cleaned!$S$2:$S$176,"Completed") -> 1 | H2: =COUNTIFS(Tracker_Cleaned!$B$2:$B$176,A2,Tracker_Cleaned!$S$2:$S$176,"Blocked") -> 0 | I2: =COUNTIFS(Tracker_Cleaned!$B$2:$B$176,A2,Tracker_Cleaned!$T$2:$T$176,"Late")+COUNTIFS(Tracker_Cleaned!$B$2:$B$176,A2,Tracker_Cleaned!$T$2:$T$176,"Overdue") -> 0 | J2: =COUNTIFS(Tracker_Cleaned!$B$2:$B$176,A2,Tracker_Cleaned!$T$2:$T$176,"No deadline") -> 0
A3: PRJ-002 | B3: Trade.Shoonya Global Dashboard (Corporate actions) | C3: Product | D3: Pradeep Thakur | E3: High | F3: =COUNTIF(Tracker_Cleaned!$B$2:$B$176,A3) -> 1 | G3: =COUNTIFS(Tracker_Cleaned!$B$2:$B$176,A3,Tracker_Cleaned!$S$2:$S$176,"Completed") -> 1 | H3: =COUNTIFS(Tracker_Cleaned!$B$2:$B$176,A3,Tracker_Cleaned!$S$2:$S$176,"Blocked") -> 0 | I3: =COUNTIFS(Tracker_Cleaned!$B$2:$B$176,A3,Tracker_Cleaned!$T$2:$T$176,"Late")+COUNTIFS(Tracker_Cleaned!$B$2:$B$176,A3,Tracker_Cleaned!$T$2:$T$176,"Overdue") -> 0 | J3: =COUNTIFS(Tracker_Cleaned!$B$2:$B$176,A3,Tracker_Cleaned!$T$2:$T$176,"No deadline") -> 0
A4: PRJ-003 | B4: Mobile-Trade.Shoonya Global Dashboard (Corporate actions) | C4: Product | D4: Pradeep Thakur | E4: High | F4: =COUNTIF(Tracker_Cleaned!$B$2:$B$176,A4) -> 1 | G4: =COUNTIFS(Tracker_Cleaned!$B$2:$B$176,A4,Tracker_Cleaned!$S$2:$S$176,"Completed") -> 1 | H4: =COUNTIFS(Tracker_Cleaned!$B$2:$B$176,A4,Tracker_Cleaned!$S$2:$S$176,"Blocked") -> 0 | I4: =COUNTIFS(Tracker_Cleaned!$B$2:$B$176,A4,Tracker_Cleaned!$T$2:$T$176,"Late")+COUNTIFS(Tracker_Cleaned!$B$2:$B$176,A4,Tracker_Cleaned!$T$2:$T$176,"Overdue") -> 0 | J4: =COUNTIFS(Tracker_Cleaned!$B$2:$B$176,A4,Tracker_Cleaned!$T$2:$T$176,"No deadline") -> 0
A5: PRJ-004 | B5: Shoonya R&R | C5: Product | D5: Pradeep Thakur | E5: High | F5: =COUNTIF(Tracker_Cleaned!$B$2:$B$176,A5) -> 1 | G5: =COUNTIFS(Tracker_Cleaned!$B$2:$B$176,A5,Tracker_Cleaned!$S$2:$S$176,"Completed") -> 0 | H5: =COUNTIFS(Tracker_Cleaned!$B$2:$B$176,A5,Tracker_Cleaned!$S$2:$S$176,"Blocked") -> 0 | I5: =COUNTIFS(Tracker_Cleaned!$B$2:$B$176,A5,Tracker_Cleaned!$T$2:$T$176,"Late")+COUNTIFS(Tracker_Cleaned!$B$2:$B$176,A5,Tracker_Cleaned!$T$2:$T$176,"Overdue") -> 0 | J5: =COUNTIFS(Tracker_Cleaned!$B$2:$B$176,A5,Tracker_Cleaned!$T$2:$T$176,"No deadline") -> 0
A6: PRJ-005 | B6: Trade Shoonya: Dark theme | C6: Product | D6: Pradeep Thakur | E6: Medium | F6: =COUNTIF(Tracker_Cleaned!$B$2:$B$176,A6) -> 1 | G6: =COUNTIFS(Tracker_Cleaned!$B$2:$B$176,A6,Tracker_Cleaned!$S$2:$S$176,"Completed") -> 0 | H6: =COUNTIFS(Tracker_Cleaned!$B$2:$B$176,A6,Tracker_Cleaned!$S$2:$S$176,"Blocked") -> 0 | I6: =COUNTIFS(Tracker_Cleaned!$B$2:$B$176,A6,Tracker_Cleaned!$T$2:$T$176,"Late")+COUNTIFS(Tracker_Cleaned!$B$2:$B$176,A6,Tracker_Cleaned!$T$2:$T$176,"Overdue") -> 1 | J6: =COUNTIFS(Tracker_Cleaned!$B$2:$B$176,A6,Tracker_Cleaned!$T$2:$T$176,"No deadline") -> 0
A7: PRJ-006 | B7: Jumpp R&R | C7: Product | D7: Pradeep Thakur | E7: High | F7: =COUNTIF(Tracker_Cleaned!$B$2:$B$176,A7) -> 1 | G7: =COUNTIFS(Tracker_Cleaned!$B$2:$B$176,A7,Tracker_Cleaned!$S$2:$S$176,"Completed") -> 0 | H7: =COUNTIFS(Tracker_Cleaned!$B$2:$B$176,A7,Tracker_Cleaned!$S$2:$S$176,"Blocked") -> 0 | I7: =COUNTIFS(Tracker_Cleaned!$B$2:$B$176,A7,Tracker_Cleaned!$T$2:$T$176,"Late")+COUNTIFS(Tracker_Cleaned!$B$2:$B$176,A7,Tracker_Cleaned!$T$2:$T$176,"Overdue") -> 1 | J7: =COUNTIFS(Tracker_Cleaned!$B$2:$B$176,A7,Tracker_Cleaned!$T$2:$T$176,"No deadline") -> 0
A8: PRJ-007 | B8: Rewards Journey UI (Milestones or Campaign) | C8: Product | D8: Pradeep Thakur | E8: High | F8: =COUNTIF(Tracker_Cleaned!$B$2:$B$176,A8) -> 1 | G8: =COUNTIFS(Tracker_Cleaned!$B$2:$B$176,A8,Tracker_Cleaned!$S$2:$S$176,"Completed") -> 0 | H8: =COUNTIFS(Tracker_Cleaned!$B$2:$B$176,A8,Tracker_Cleaned!$S$2:$S$176,"Blocked") -> 0 | I8: =COUNTIFS(Tracker_Cleaned!$B$2:$B$176,A8,Tracker_Cleaned!$T$2:$T$176,"Late")+COUNTIFS(Tracker_Cleaned!$B$2:$B$176,A8,Tracker_Cleaned!$T$2:$T$176,"Overdue") -> 1 | J8: =COUNTIFS(Tracker_Cleaned!$B$2:$B$176,A8,Tracker_Cleaned!$T$2:$T$176,"No deadline") -> 0
A9: PRJ-008 | B9: Digital Silver | C9: Product | D9: Pradeep Thakur | E9: High | F9: =COUNTIF(Tracker_Cleaned!$B$2:$B$176,A9) -> 1 | G9: =COUNTIFS(Tracker_Cleaned!$B$2:$B$176,A9,Tracker_Cleaned!$S$2:$S$176,"Completed") -> 0 | H9: =COUNTIFS(Tracker_Cleaned!$B$2:$B$176,A9,Tracker_Cleaned!$S$2:$S$176,"Blocked") -> 0 | I9: =COUNTIFS(Tracker_Cleaned!$B$2:$B$176,A9,Tracker_Cleaned!$T$2:$T$176,"Late")+COUNTIFS(Tracker_Cleaned!$B$2:$B$176,A9,Tracker_Cleaned!$T$2:$T$176,"Overdue") -> 1 | J9: =COUNTIFS(Tracker_Cleaned!$B$2:$B$176,A9,Tracker_Cleaned!$T$2:$T$176,"No deadline") -> 0
A10: PRJ-009 | B10: Digital Silver SIP | C10: Product | D10: Pradeep Thakur | E10: High | F10: =COUNTIF(Tracker_Cleaned!$B$2:$B$176,A10) -> 1 | G10: =COUNTIFS(Tracker_Cleaned!$B$2:$B$176,A10,Tracker_Cleaned!$S$2:$S$176,"Completed") -> 0 | H10: =COUNTIFS(Tracker_Cleaned!$B$2:$B$176,A10,Tracker_Cleaned!$S$2:$S$176,"Blocked") -> 0 | I10: =COUNTIFS(Tracker_Cleaned!$B$2:$B$176,A10,Tracker_Cleaned!$T$2:$T$176,"Late")+COUNTIFS(Tracker_Cleaned!$B$2:$B$176,A10,Tracker_Cleaned!$T$2:$T$176,"Overdue") -> 1 | J10: =COUNTIFS(Tracker_Cleaned!$B$2:$B$176,A10,Tracker_Cleaned!$T$2:$T$176,"No deadline") -> 0
A11: PRJ-010 | B11: Digital Gold SIP | C11: Product | D11: Pradeep Thakur | E11: High | F11: =COUNTIF(Tracker_Cleaned!$B$2:$B$176,A11) -> 1 | G11: =COUNTIFS(Tracker_Cleaned!$B$2:$B$176,A11,Tracker_Cleaned!$S$2:$S$176,"Completed") -> 0 | H11: =COUNTIFS(Tracker_Cleaned!$B$2:$B$176,A11,Tracker_Cleaned!$S$2:$S$176,"Blocked") -> 0 | I11: =COUNTIFS(Tracker_Cleaned!$B$2:$B$176,A11,Tracker_Cleaned!$T$2:$T$176,"Late")+COUNTIFS(Tracker_Cleaned!$B$2:$B$176,A11,Tracker_Cleaned!$T$2:$T$176,"Overdue") -> 1 | J11: =COUNTIFS(Tracker_Cleaned!$B$2:$B$176,A11,Tracker_Cleaned!$T$2:$T$176,"No deadline") -> 0
A12: PRJ-011 | B12: Physical Silver | C12: Product | D12: Pradeep Thakur | E12: High | F12: =COUNTIF(Tracker_Cleaned!$B$2:$B$176,A12) -> 1 | G12: =COUNTIFS(Tracker_Cleaned!$B$2:$B$176,A12,Tracker_Cleaned!$S$2:$S$176,"Completed") -> 0 | H12: =COUNTIFS(Tracker_Cleaned!$B$2:$B$176,A12,Tracker_Cleaned!$S$2:$S$176,"Blocked") -> 0 | I12: =COUNTIFS(Tracker_Cleaned!$B$2:$B$176,A12,Tracker_Cleaned!$T$2:$T$176,"Late")+COUNTIFS(Tracker_Cleaned!$B$2:$B$176,A12,Tracker_Cleaned!$T$2:$T$176,"Overdue") -> 1 | J12: =COUNTIFS(Tracker_Cleaned!$B$2:$B$176,A12,Tracker_Cleaned!$T$2:$T$176,"No deadline") -> 0
A13: PRJ-012 | B13: Physical Gold | C13: Product | D13: Pradeep Thakur | E13: High | F13: =COUNTIF(Tracker_Cleaned!$B$2:$B$176,A13) -> 1 | G13: =COUNTIFS(Tracker_Cleaned!$B$2:$B$176,A13,Tracker_Cleaned!$S$2:$S$176,"Completed") -> 0 | H13: =COUNTIFS(Tracker_Cleaned!$B$2:$B$176,A13,Tracker_Cleaned!$S$2:$S$176,"Blocked") -> 0 | I13: =COUNTIFS(Tracker_Cleaned!$B$2:$B$176,A13,Tracker_Cleaned!$T$2:$T$176,"Late")+COUNTIFS(Tracker_Cleaned!$B$2:$B$176,A13,Tracker_Cleaned!$T$2:$T$176,"Overdue") -> 1 | J13: =COUNTIFS(Tracker_Cleaned!$B$2:$B$176,A13,Tracker_Cleaned!$T$2:$T$176,"No deadline") -> 0
... A30: PRJ-029 | B30: Buyback Feature Implementation | C30: Operations & BO | D30: Pawan | E30: Medium | F30: =COUNTIF(Tracker_Cleaned!$B$2:$B$176,A30) -> 2 | G30: =COUNTIFS(Tracker_Cleaned!$B$2:$B$176,A30,Tracker_Cleaned!$S$2:$S$176,"Completed") -> 0 | H30: =COUNTIFS(Tracker_Cleaned!$B$2:$B$176,A30,Tracker_Cleaned!$S$2:$S$176,"Blocked") -> 0 | I30: =COUNTIFS(Tracker_Cleaned!$B$2:$B$176,A30,Tracker_Cleaned!$T$2:$T$176,"Late")+COUNTIFS(Tracker_Cleaned!$B$2:$B$176,A30,Tracker_Cleaned!$T$2:$T$176,"Overdue") -> 0 | J30: =COUNTIFS(Tracker_Cleaned!$B$2:$B$176,A30,Tracker_Cleaned!$T$2:$T$176,"No deadline") -> 2
A31: PRJ-030 | B31: SenS-AI 1.1 Enhancement | C31: Product | E31: High | F31: =COUNTIF(Tracker_Cleaned!$B$2:$B$176,A31) -> 5 | G31: =COUNTIFS(Tracker_Cleaned!$B$2:$B$176,A31,Tracker_Cleaned!$S$2:$S$176,"Completed") -> 0 | H31: =COUNTIFS(Tracker_Cleaned!$B$2:$B$176,A31,Tracker_Cleaned!$S$2:$S$176,"Blocked") -> 5 | I31: =COUNTIFS(Tracker_Cleaned!$B$2:$B$176,A31,Tracker_Cleaned!$T$2:$T$176,"Late")+COUNTIFS(Tracker_Cleaned!$B$2:$B$176,A31,Tracker_Cleaned!$T$2:$T$176,"Overdue") -> 5 | J31: =COUNTIFS(Tracker_Cleaned!$B$2:$B$176,A31,Tracker_Cleaned!$T$2:$T$176,"No deadline") -> 0 | K31: Set owner
A32: PRJ-031 | B32: fno Edge | C32: Product | E32: High | F32: =COUNTIF(Tracker_Cleaned!$B$2:$B$176,A32) -> 4 | G32: =COUNTIFS(Tracker_Cleaned!$B$2:$B$176,A32,Tracker_Cleaned!$S$2:$S$176,"Completed") -> 0 | H32: =COUNTIFS(Tracker_Cleaned!$B$2:$B$176,A32,Tracker_Cleaned!$S$2:$S$176,"Blocked") -> 0 | I32: =COUNTIFS(Tracker_Cleaned!$B$2:$B$176,A32,Tracker_Cleaned!$T$2:$T$176,"Late")+COUNTIFS(Tracker_Cleaned!$B$2:$B$176,A32,Tracker_Cleaned!$T$2:$T$176,"Overdue") -> 4 | J32: =COUNTIFS(Tracker_Cleaned!$B$2:$B$176,A32,Tracker_Cleaned!$T$2:$T$176,"No deadline") -> 0 | K32: Set owner
A33: PRJ-032 | B33: Automating the current PRISM process | C33: Product | E33: Medium | F33: =COUNTIF(Tracker_Cleaned!$B$2:$B$176,A33) -> 3 | G33: =COUNTIFS(Tracker_Cleaned!$B$2:$B$176,A33,Tracker_Cleaned!$S$2:$S$176,"Completed") -> 0 | H33: =COUNTIFS(Tracker_Cleaned!$B$2:$B$176,A33,Tracker_Cleaned!$S$2:$S$176,"Blocked") -> 0 | I33: =COUNTIFS(Tracker_Cleaned!$B$2:$B$176,A33,Tracker_Cleaned!$T$2:$T$176,"Late")+COUNTIFS(Tracker_Cleaned!$B$2:$B$176,A33,Tracker_Cleaned!$T$2:$T$176,"Overdue") -> 0 | J33: =COUNTIFS(Tracker_Cleaned!$B$2:$B$176,A33,Tracker_Cleaned!$T$2:$T$176,"No deadline") -> 0 | K33: Set owner
A34: PRJ-033 | B34: MTF Margin increase | C34: Product | E34: High | F34: =COUNTIF(Tracker_Cleaned!$B$2:$B$176,A34) -> 3 | G34: =COUNTIFS(Tracker_Cleaned!$B$2:$B$176,A34,Tracker_Cleaned!$S$2:$S$176,"Completed") -> 0 | H34: =COUNTIFS(Tracker_Cleaned!$B$2:$B$176,A34,Tracker_Cleaned!$S$2:$S$176,"Blocked") -> 0 | I34: =COUNTIFS(Tracker_Cleaned!$B$2:$B$176,A34,Tracker_Cleaned!$T$2:$T$176,"Late")+COUNTIFS(Tracker_Cleaned!$B$2:$B$176,A34,Tracker_Cleaned!$T$2:$T$176,"Overdue") -> 3 | J34: =COUNTIFS(Tracker_Cleaned!$B$2:$B$176,A34,Tracker_Cleaned!$T$2:$T$176,"No deadline") -> 0 | K34: Set owner
